Workbook

Sheet Sheet1
B3: No | C3: Raw Participant Name | D3: Capital Letters (All) | E3: Lowercase (All) | F3: Capital Letter at the beginning | G3: Sentences Case | H3: Typeface | I3: Capital Letters (Initial and Final) | J3: Raw School Data | K3: School
B4: Contoh | C4: aNdi Setiadi | D4: ANDI SETIADI | E4: andi setiadi | F4: Andi Setiadi | G4: Andi setiadi | H4: Mixed Letters | I4: Andi setiadI | J4: sD SiNdanGgalih | K4: SD Sindanggalih
B6: 1 | C6: andi saputra | D6: =UPPER(C6) -> ANDI SAPUTRA | E6: =LOWER(C6) -> andi saputra | F6: =PROPER(C6) -> Andi Saputra | G6: =UPPER(LEFT(C6,1))&LOWER(RIGHT(C6,LEN(C6)-1)) -> Andi saputra | H6: =IF(EXACT(C6,UPPER(C6)),"Capital Letters",IF(EXACT(C6,LOWER(C6)),"Lowercase","Mixed Letters")) -> Lowercase | I6: =UPPER(LEFT(C6,1))&LOWER(MID(C6,2,LEN(C6)-2))&UPPER(RIGHT(C6,1)) -> Andi saputrA | J6: sD nUsAnTaRa cEmErLaNg | K6: =UPPER(LEFT(J6,FIND(" ",J6)-1))&" "&PROPER(MID(J6,FIND(" ",J6)+1,LEN(J6))) -> SD Nusantara Cemerlang
B7: 2 | C7: bUDi sANtoSo | D7: =UPPER(C7) -> BUDI SANTOSO | E7: =LOWER(C7) -> budi santoso | F7: =PROPER(C7) -> Budi Santoso | G7: =UPPER(LEFT(C7,1))&LOWER(RIGHT(C7,LEN(C7)-1)) -> Budi santoso | H7: =IF(EXACT(C7,UPPER(C7)),"Capital Letters",IF(EXACT(C7,LOWER(C7)),"Lowercase","Mixed Letters")) -> Mixed Letters | I7: =UPPER(LEFT(C7,1))&LOWER(MID(C7,2,LEN(C7)-2))&UPPER(RIGHT(C7,1)) -> Budi santosO | J7: SmP bInA kArYa uTaMa | K7: =UPPER(LEFT(J7,FIND(" ",J7)-1))&" "&PROPER(MID(J7,FIND(" ",J7)+1,LEN(J7))) -> SMP Bina Karya Utama
B8: 3 | C8: CITRA DEWI | D8: =UPPER(C8) -> CITRA DEWI | E8: =LOWER(C8) -> citra dewi | F8: =PROPER(C8) -> Citra Dewi | G8: =UPPER(LEFT(C8,1))&LOWER(RIGHT(C8,LEN(C8)-1)) -> Citra dewi | H8: =IF(EXACT(C8,UPPER(C8)),"Capital Letters",IF(EXACT(C8,LOWER(C8)),"Lowercase","Mixed Letters")) -> Capital Letters | I8: =UPPER(LEFT(C8,1))&LOWER(MID(C8,2,LEN(C8)-2))&UPPER(RIGHT(C8,1)) -> Citra dewI | J8: sMa gLoBaL pReStAsI | K8: =UPPER(LEFT(J8,FIND(" ",J8)-1))&" "&PROPER(MID(J8,FIND(" ",J8)+1,LEN(J8))) -> SMA Global Prestasi
B9: 4 | C9: dIaN prAseTyo | D9: =UPPER(C9) -> DIAN PRASETYO | E9: =LOWER(C9) -> dian prasetyo | F9: =PROPER(C9) -> Dian Prasetyo | G9: =UPPER(LEFT(C9,1))&LOWER(RIGHT(C9,LEN(C9)-1)) -> Dian prasetyo | H9: =IF(EXACT(C9,UPPER(C9)),"Capital Letters",IF(EXACT(C9,LOWER(C9)),"Lowercase","Mixed Letters")) -> Mixed Letters | I9: =UPPER(LEFT(C9,1))&LOWER(MID(C9,2,LEN(C9)-2))&UPPER(RIGHT(C9,1)) -> Dian prasetyO | J9: Sd pElItA iNsAn mUlIa | K9: =UPPER(LEFT(J9,FIND(" ",J9)-1))&" "&PROPER(MID(J9,FIND(" ",J9)+1,LEN(J9))) -> SD Pelita Insan Mulia
B10: 5 | C10: EKO WAHYUDI | D10: =UPPER(C10) -> EKO WAHYUDI | E10: =LOWER(C10) -> eko wahyudi | F10: =PROPER(C10) -> Eko Wahyudi | G10: =UPPER(LEFT(C10,1))&LOWER(RIGHT(C10,LEN(C10)-1)) -> Eko wahyudi | H10: =IF(EXACT(C10,UPPER(C10)),"Capital Letters",IF(EXACT(C10,LOWER(C10)),"Lowercase","Mixed Letters")) -> Capital Letters | I10: =UPPER(LEFT(C10,1))&LOWER(MID(C10,2,LEN(C10)-2))&UPPER(RIGHT(C10,1)) -> Eko wahyudI | J10: SmA sInAr aBuDi | K10: =UPPER(LEFT(J10,FIND(" ",J10)-1))&" "&PROPER(MID(J10,FIND(" ",J10)+1,LEN(J10))) -> SMA Sinar Abudi
B11: 6 | C11: fitri anjani | D11: =UPPER(C11) -> FITRI ANJANI | E11: =LOWER(C11) -> fitri anjani | F11: =PROPER(C11) -> Fitri Anjani | G11: =UPPER(LEFT(C11,1))&LOWER(RIGHT(C11,LEN(C11)-1)) -> Fitri anjani | H11: =IF(EXACT(C11,UPPER(C11)),"Capital Letters",IF(EXACT(C11,LOWER(C11)),"Lowercase","Mixed Letters")) -> Lowercase | I11: =UPPER(LEFT(C11,1))&LOWER(MID(C11,2,LEN(C11)-2))&UPPER(RIGHT(C11,1)) -> Fitri anjanI | J11: sMp tUnAs bAnGsA | K11: =UPPER(LEFT(J11,FIND(" ",J11)-1))&" "&PROPER(MID(J11,FIND(" ",J11)+1,LEN(J11))) -> SMP Tunas Bangsa
B12: 7 | C12: gAlIh pErMAnA | D12: =UPPER(C12) -> GALIH PERMANA | E12: =LOWER(C12) -> galih permana | F12: =PROPER(C12) -> Galih Permana | G12: =UPPER(LEFT(C12,1))&LOWER(RIGHT(C12,LEN(C12)-1)) -> Galih permana | H12: =IF(EXACT(C12,UPPER(C12)),"Capital Letters",IF(EXACT(C12,LOWER(C12)),"Lowercase","Mixed Letters")) -> Mixed Letters | I12: =UPPER(LEFT(C12,1))&LOWER(MID(C12,2,LEN(C12)-2))&UPPER(RIGHT(C12,1)) -> Galih permanA | J12: SmA cEnDeKiA mAnDiRi | K12: =UPPER(LEFT(J12,FIND(" ",J12)-1))&" "&PROPER(MID(J12,FIND(" ",J12)+1,LEN(J12))) -> SMA Cendekia Mandiri
B13: 8 | C13: heNdRA gUnAwAn | D13: =UPPER(C13) -> HENDRA GUNAWAN | E13: =LOWER(C13) -> hendra gunawan | F13: =PROPER(C13) -> Hendra Gunawan | G13: =UPPER(LEFT(C13,1))&LOWER(RIGHT(C13,LEN(C13)-1)) -> Hendra gunawan | H13: =IF(EXACT(C13,UPPER(C13)),"Capital Letters",IF(EXACT(C13,LOWER(C13)),"Lowercase","Mixed Letters")) -> Mixed Letters | I13: =UPPER(LEFT(C13,1))&LOWER(MID(C13,2,LEN(C13)-2))&UPPER(RIGHT(C13,1)) -> Hendra gunawaN | J13: sD bHaKtI pErTiWi | K13: =UPPER(LEFT(J13,FIND(" ",J13)-1))&" "&PROPER(MID(J13,FIND(" ",J13)+1,LEN(J13))) -> SD Bhakti Pertiwi
B14: 9 | C14: indah sari | D14: =UPPER(C14) -> INDAH SARI | E14: =LOWER(C14) -> indah sari | F14: =PROPER(C14) -> Indah Sari | G14: =UPPER(LEFT(C14,1))&LOWER(RIGHT(C14,LEN(C14)-1)) -> Indah sari | H14: =IF(EXACT(C14,UPPER(C14)),"Capital Letters",IF(EXACT(C14,LOWER(C14)),"Lowercase","Mixed Letters")) -> Lowercase | I14: =UPPER(LEFT(C14,1))&LOWER(MID(C14,2,LEN(C14)-2))&UPPER(RIGHT(C14,1)) -> Indah sarI | J14: sMp mEkAr jAyA aBaDi | K14: =UPPER(LEFT(J14,FIND(" ",J14)-1))&" "&PROPER(MID(J14,FIND(" ",J14)+1,LEN(J14))) -> SMP Mekar Jaya Abadi
B15: 10 | C15: JOKO SUSILO | D15: =UPPER(C15) -> JOKO SUSILO | E15: =LOWER(C15) -> joko susilo | F15: =PROPER(C15) -> Joko Susilo | G15: =UPPER(LEFT(C15,1))&LOWER(RIGHT(C15,LEN(C15)-1)) -> Joko susilo | H15: =IF(EXACT(C15,UPPER(C15)),"Capital Letters",IF(EXACT(C15,LOWER(C15)),"Lowercase","Mixed Letters")) -> Capital Letters | I15: =UPPER(LEFT(C15,1))&LOWER(MID(C15,2,LEN(C15)-2))&UPPER(RIGHT(C15,1)) -> Joko susilO | J15: SmA pUsAkA nUsAnTaRa | K15: =UPPER(LEFT(J15,FIND(" ",J15)-1))&" "&PROPER(MID(J15,FIND(" ",J15)+1,LEN(J15))) -> SMA Pusaka Nusantara
B16: 11 | C16: KaRTiKa pUtRi | D16: =UPPER(C16) -> KARTIKA PUTRI | E16: =LOWER(C16) -> kartika putri | F16: =PROPER(C16) -> Kartika Putri | G16: =UPPER(LEFT(C16,1))&LOWER(RIGHT(C16,LEN(C16)-1)) -> Kartika putri | H16: =IF(EXACT(C16,UPPER(C16)),"Capital Letters",IF(EXACT(C16,LOWER(C16)),"Lowercase","Mixed Letters")) -> Mixed Letters | I16: =UPPER(LEFT(C16,1))&LOWER(MID(C16,2,LEN(C16)-2))&UPPER(RIGHT(C16,1)) -> Kartika putrI | J16: sD cItRa hArApAn | K16: =UPPER(LEFT(J16,FIND(" ",J16)-1))&" "&PROPER(MID(J16,FIND(" ",J16)+1,LEN(J16))) -> SD Citra Harapan
B17: 12 | C17: LESTARI AYU | D17: =UPPER(C17) -> LESTARI AYU | E17: =LOWER(C17) -> lestari ayu | F17: =PROPER(C17) -> Lestari Ayu | G17: =UPPER(LEFT(C17,1))&LOWER(RIGHT(C17,LEN(C17)-1)) -> Lestari ayu | H17: =IF(EXACT(C17,UPPER(C17)),"Capital Letters",IF(EXACT(C17,LOWER(C17)),"Lowercase","Mixed Letters")) -> Capital Letters | I17: =UPPER(LEFT(C17,1))&LOWER(MID(C17,2,LEN(C17)-2))&UPPER(RIGHT(C17,1)) -> Lestari ayU | J17: sMp aRgA sEnToSa | K17: =UPPER(LEFT(J17,FIND(" ",J17)-1))&" "&PROPER(MID(J17,FIND(" ",J17)+1,LEN(J17))) -> SMP Arga Sentosa
... B20: 15 | C20: Lusi atMAjaya | D20: =UPPER(C20) -> LUSI ATMAJAYA | E20: =LOWER(C20) -> lusi atmajaya | F20: =PROPER(C20) -> Lusi Atmajaya | G20: =UPPER(LEFT(C20,1))&LOWER(RIGHT(C20,LEN(C20)-1)) -> Lusi atmajaya | H20: =IF(EXACT(C20,UPPER(C20)),"Capital Letters",IF(EXACT(C20,LOWER(C20)),"Lowercase","Mixed Letters")) -> Mixed Letters | I20: =UPPER(LEFT(C20,1))&LOWER(MID(C20,2,LEN(C20)-2))&UPPER(RIGHT(C20,1)) -> Lusi atmajayA | J20: sMp lEnSa iLmU | K20: =UPPER(LEFT(J20,FIND(" ",J20)-1))&" "&PROPER(MID(J20,FIND(" ",J20)+1,LEN(J20))) -> SMP Lensa Ilmu

Sheet Sheet2
B2: Departure Date | C2: Passenger Name | D2: Ticket Code | E2: Class | F2: Ticket Type | G2: Ticket Price | H2: Discount | I2: Net Price
B3: 45155 | C3: Anisa Yunia | D3: EKOD | E3: =HLOOKUP(LEFT(D3,3),$C$14:$E$15,2,0) -> Economics | F3: =VLOOKUP(RIGHT(D3,1),$B$18:$C$21,2,0) -> Adults | G3: =INDEX($D$19:$F$21,MATCH(RIGHT(D3,1),$B$19:$B$21,0),MATCH(E3,$D$18:$F$18,0)) -> 75000 | H3: =IF(B3<DATE(2023,9,1),G3*10%,0) -> 7500 | I3: =G3-H3 -> 67500
B4: 45170 | C4: Budi Susanto | D4: EXCA | E4: =HLOOKUP(LEFT(D4,3),$C$14:$E$15,2,0) -> Executive | F4: =VLOOKUP(RIGHT(D4,1),$B$18:$C$21,2,0) -> Children | G4: =INDEX($D$19:$F$21,MATCH(RIGHT(D4,1),$B$19:$B$21,0),MATCH(E4,$D$18:$F$18,0)) -> 100000 | H4: =IF(B4<DATE(2023,9,1),G4*10%,0) -> 0 | I4: =G4-H4 -> 100000
B5: 45169 | C5: Rizki Soleh | D5: BISA | E5: =HLOOKUP(LEFT(D5,3),$C$14:$E$15,2,0) -> Business | F5: =VLOOKUP(RIGHT(D5,1),$B$18:$C$21,2,0) -> Children | G5: =INDEX($D$19:$F$21,MATCH(RIGHT(D5,1),$B$19:$B$21,0),MATCH(E5,$D$18:$F$18,0)) -> 70000 | H5: =IF(B5<DATE(2023,9,1),G5*10%,0) -> 7000 | I5: =G5-H5 -> 63000
B6: 45174 | C6: Abdul Hadi | D6: EXCD | E6: =HLOOKUP(LEFT(D6,3),$C$14:$E$15,2,0) -> Executive | F6: =VLOOKUP(RIGHT(D6,1),$B$18:$C$21,2,0) -> Adults | G6: =INDEX($D$19:$F$21,MATCH(RIGHT(D6,1),$B$19:$B$21,0),MATCH(E6,$D$18:$F$18,0)) -> 150000 | H6: =IF(B6<DATE(2023,9,1),G6*10%,0) -> 0 | I6: =G6-H6 -> 150000
B7: 45163 | C7: Dewi Sandra | D7: EKOL | E7: =HLOOKUP(LEFT(D7,3),$C$14:$E$15,2,0) -> Economics | F7: =VLOOKUP(RIGHT(D7,1),$B$18:$C$21,2,0) -> Elderly | G7: =INDEX($D$19:$F$21,MATCH(RIGHT(D7,1),$B$19:$B$21,0),MATCH(E7,$D$18:$F$18,0)) -> 60000 | H7: =IF(B7<DATE(2023,9,1),G7*10%,0) -> 6000 | I7: =G7-H7 -> 54000
B8: 45179 | C8: Nina Adriana | D8: BISD | E8: =HLOOKUP(LEFT(D8,3),$C$14:$E$15,2,0) -> Business | F8: =VLOOKUP(RIGHT(D8,1),$B$18:$C$21,2,0) -> Adults | G8: =INDEX($D$19:$F$21,MATCH(RIGHT(D8,1),$B$19:$B$21,0),MATCH(E8,$D$18:$F$18,0)) -> 100000 | H8: =IF(B8<DATE(2023,9,1),G8*10%,0) -> 0 | I8: =G8-H8 -> 100000
B9: 45169 | C9: Ali Akbar | D9: EXCL | E9: =HLOOKUP(LEFT(D9,3),$C$14:$E$15,2,0) -> Executive | F9: =VLOOKUP(RIGHT(D9,1),$B$18:$C$21,2,0) -> Elderly | G9: =INDEX($D$19:$F$21,MATCH(RIGHT(D9,1),$B$19:$B$21,0),MATCH(E9,$D$18:$F$18,0)) -> 120000 | H9: =IF(B9<DATE(2023,9,1),G9*10%,0) -> 12000 | I9: =G9-H9 -> 108000
B11: 10% discount on ticket price for departures before September 1, 2023
B13: Class Table
B14: Class Code | C14: EKO | D14: BIS | E14: EXC
B15: Class | C15: Economics | D15: Business | E15: Executive
B17: Ticket Type Table
B18: Ticket Code | C18: Ticket Type | D18: Economics | E18: Business | F18: Executive
B19: A | C19: Children | D19: 50000 | E19: 70000 | F19: 100000
B20: D | C20: Adults | D20: 75000 | E20: 100000 | F20: 150000
B21: L | C21: Elderly | D21: 60000 | E21: 85000 | F21: 120000

Sheet Sheet3
B2: KODE | C2: DIVISI | D2: GAJI POKOK | F2: Kode = 1 | G2: Kepala
B3: A | C3: Distributor | D3: 2500000 | F3: Kode = 2 | G3: Staff | L3: 1 | M3: 2 | N3: 3 | O3: 4 | Q3: 5 | R3: 6
B4: B | C4: Engineering | D4: 2300000 | F4: Kode = 3 | G4: Operator | I4: NO | J4: KODE | K4: NAMA | L4: JABATAN | M4: STATUS | N4: DIVISI | O4: GAJI POKOK | P4: JMLH ANAK | Q4: TUNJ. ANAK | R4: TOTAL GAJI
B5: C | C5: Produksi | D5: 2000000 | I5: Contoh | J5: C-3-M | K5: Agus Mulyono | L5: Operator | M5: Married | N5: Produksi | O5: 2000000 | P5: 2 | Q5: 50000 | R5: 2050000
B6: D | C6: Quality Control | D6: 2600000 | F6: Kode = S | G6: Single
F7: Kode = M | G7: Married | I7: 1 | J7: A-1-M | K7: Dewi Anugrah | L7: =VLOOKUP("Kode = "&MID(J7,3,1),$F$2:$G$4,2,0) -> Kepala | M7: =VLOOKUP("Kode = "&RIGHT(J7,1),$F$6:$G$7,2,0) -> Married | N7: =VLOOKUP(LEFT(J7,1),$B$3:$D$6,2,0) -> Distributor | O7: =VLOOKUP(LEFT(J7,1),$B$3:$D$6,3,0) -> 2500000 | P7: 2 | Q7: =$C$9*P7 -> 50000 | R7: =O7+Q7 -> 2550000
I8: 2 | J8: A-2-M | K8: Anton Susilo | L8: =VLOOKUP("Kode = "&MID(J8,3,1),$F$2:$G$4,2,0) -> Staff | M8: =VLOOKUP("Kode = "&RIGHT(J8,1),$F$6:$G$7,2,0) -> Married | N8: =VLOOKUP(LEFT(J8,1),$B$3:$D$6,2,0) -> Distributor | O8: =VLOOKUP(LEFT(J8,1),$B$3:$D$6,3,0) -> 2500000 | P8: 3 | Q8: =$C$9*P8 -> 75000 | R8: =O7+Q7 -> 2550000
B9: Tunj. Anak | C9: 25000 | I9: 3 | J9: B-1-S | K9: Wulan Sari | L9: =VLOOKUP("Kode = "&MID(J9,3,1),$F$2:$G$4,2,0) -> Kepala | M9: =VLOOKUP("Kode = "&RIGHT(J9,1),$F$6:$G$7,2,0) -> Single | N9: =VLOOKUP(LEFT(J9,1),$B$3:$D$6,2,0) -> Engineering | O9: =VLOOKUP(LEFT(J9,1),$B$3:$D$6,3,0) -> 2300000 | P9: 0 | Q9: =$C$9*P9 -> 0 | R9: =O8+Q8 -> 2575000
I10: 4 | J10: B-3-M | K10: Toni Sutisna | L10: =VLOOKUP("Kode = "&MID(J10,3,1),$F$2:$G$4,2,0) -> Operator | M10: =VLOOKUP("Kode = "&RIGHT(J10,1),$F$6:$G$7,2,0) -> Married | N10: =VLOOKUP(LEFT(J10,1),$B$3:$D$6,2,0) -> Engineering | O10: =VLOOKUP(LEFT(J10,1),$B$3:$D$6,3,0) -> 2300000 | P10: 1 | Q10: =$C$9*P10 -> 25000 | R10: =O9+Q9 -> 2300000
I11: 5 | J11: A-3-S | K11: Didik Wahyudi | L11: =VLOOKUP("Kode = "&MID(J11,3,1),$F$2:$G$4,2,0) -> Operator | M11: =VLOOKUP("Kode = "&RIGHT(J11,1),$F$6:$G$7,2,0) -> Single | N11: =VLOOKUP(LEFT(J11,1),$B$3:$D$6,2,0) -> Distributor | O11: =VLOOKUP(LEFT(J11,1),$B$3:$D$6,3,0) -> 2500000 | P11: 0 | Q11: =$C$9*P11 -> 0 | R11: =O10+Q10 -> 2325000
I12: 6 | J12: D-3-M | K12: Tono Hendra | L12: =VLOOKUP("Kode = "&MID(J12,3,1),$F$2:$G$4,2,0) -> Operator | M12: =VLOOKUP("Kode = "&RIGHT(J12,1),$F$6:$G$7,2,0) -> Married | N12: =VLOOKUP(LEFT(J12,1),$B$3:$D$6,2,0) -> Quality Control | O12: =VLOOKUP(LEFT(J12,1),$B$3:$D$6,3,0) -> 2600000 | P12: 3 | Q12: =$C$9*P12 -> 75000 | R12: =O11+Q11 -> 2500000
I13: 7 | J13: D-2-S | K13: Bayu Aji | L13: =VLOOKUP("Kode = "&MID(J13,3,1),$F$2:$G$4,2,0) -> Staff | M13: =VLOOKUP("Kode = "&RIGHT(J13,1),$F$6:$G$7,2,0) -> Single | N13: =VLOOKUP(LEFT(J13,1),$B$3:$D$6,2,0) -> Quality Control | O13: =VLOOKUP(LEFT(J13,1),$B$3:$D$6,3,0) -> 2600000 | P13: 0 | Q13: =$C$9*P13 -> 0 | R13: =O12+Q12 -> 2675000
I14: 8 | J14: B-2-S | K14: Andi Setiadi | L14: =VLOOKUP("Kode = "&MID(J14,3,1),$F$2:$G$4,2,0) -> Staff | M14: =VLOOKUP("Kode = "&RIGHT(J14,1),$F$6:$G$7,2,0) -> Single | N14: =VLOOKUP(LEFT(J14,1),$B$3:$D$6,2,0) -> Engineering | O14: =VLOOKUP(LEFT(J14,1),$B$3:$D$6,3,0) -> 2300000 | P14: 0 | Q14: =$C$9*P14 -> 0 | R14: =O13+Q13 -> 2600000
I15: 9 | J15: C-2-M | K15: Ananda Putra | L15: =VLOOKUP("Kode = "&MID(J15,3,1),$F$2:$G$4,2,0) -> Staff | M15: =VLOOKUP("Kode = "&RIGHT(J15,1),$F$6:$G$7,2,0) -> Married | N15: =VLOOKUP(LEFT(J15,1),$B$3:$D$6,2,0) -> Produksi | O15: =VLOOKUP(LEFT(J15,1),$B$3:$D$6,3,0) -> 2000000 | P15: 1 | Q15: =$C$9*P15 -> 25000 | R15: =O14+Q14 -> 2300000
I16: 10 | J16: C-1-M | K16: Rina Nurmalasari | L16: =VLOOKUP("Kode = "&MID(J16,3,1),$F$2:$G$4,2,0) -> Kepala | M16: =VLOOKUP("Kode = "&RIGHT(J16,1),$F$6:$G$7,2,0) -> Married | N16: =VLOOKUP(LEFT(J16,1),$B$3:$D$6,2,0) -> Produksi | O16: =VLOOKUP(LEFT(J16,1),$B$3:$D$6,3,0) -> 2000000 | P16: 0 | Q16: =$C$9*P16 -> 0 | R16: =O15+Q15 -> 2025000
Q17: Total Seluruh Gaji | R17: =SUM(R7:R16) -> 24400000
Q18: Gaji Terbesar | R18: =MAX(R7:R16) -> 2675000
Q19: Gaji Terendah | R19: =MIN(R7:R16) -> 2025000
Q20: Gaji Rata-Rata | R20: =AVERAGE(R7:R16) -> 2440000
Q21: Jumlah Pegawai | R21: =COUNT(R7:R16) -> 10

Sheet Sheet4
B2: HARGA JUAL : HARGA POKOK +25% HP
F3: NO | G3: KODE | H3: TERJUAL | I3: NAMA BARANG-MERK | J3: HARGA POKOK | K3: TOTAL HARGA JUAL | L3: DISCOUNT | M3: BONUS | N3: TOTAL
B4: DISCOUNT | F4: 1 | G4: TV-99-EUR-M2 | H4: 7 | I4: =VLOOKUP(LEFT(G4,2),$F$16:$G$24,2,0)&"-"&HLOOKUP(RIGHT(G4,2),$G$26:$M$27,2,0) -> Televisi-LG | J4: =VALUE(MID(G4,4,2))*VLOOKUP(MID(G4,7,3),$I$17:$K$21,3,0) -> 1980000 | K4: =H4*(J4+(25%*J4)) -> 17325000 | L4: =IF(K4>=10000000,K4*25%,IF(K4>=8000000,K4*20%,IF(K4>=5000000,K4*15%,IF(K4>=3000000,K4*10%,IF(K4>=2000000,K4*5%,0))))) -> 4331250 | M4: =IF(AND(K4>=5000000,L4>=2000000),"Power Bank",IF(AND(K4>=2000000,L4>=500000),"TWS",IF(AND(K4<2000000,L4<500000),"Voucher","-"))) -> Power Bank | N4: =K4-L4 -> 12993750
F5: 2 | G5: HP-90-CAD-M1 | H5: 6 | I5: =VLOOKUP(LEFT(G5,2),$F$16:$G$24,2,0)&"-"&HLOOKUP(RIGHT(G5,2),$G$26:$M$27,2,0) -> Handphone-Samsung | J5: =VALUE(MID(G5,4,2))*VLOOKUP(MID(G5,7,3),$I$17:$K$21,3,0) -> 1125000 | K5: =H5*(J5+(25%*J5)) -> 8437500 | L5: =IF(K5>=10000000,K5*25%,IF(K5>=8000000,K5*20%,IF(K5>=5000000,K5*15%,IF(K5>=3000000,K5*10%,IF(K5>=2000000,K5*5%,0))))) -> 1687500 | M5: =IF(AND(K5>=5000000,L5>=2000000),"Power Bank",IF(AND(K5>=2000000,L5>=500000),"TWS",IF(AND(K5<2000000,L5<500000),"Voucher","-"))) -> TWS | N5: =K5-L5 -> 6750000
B6: 0.25 | C6: ≥ 10.000.000 | F6: 3 | G6: TV-88-USD-M4 | H6: 4 | I6: =VLOOKUP(LEFT(G6,2),$F$16:$G$24,2,0)&"-"&HLOOKUP(RIGHT(G6,2),$G$26:$M$27,2,0) -> Televisi-Panasonic | J6: =VALUE(MID(G6,4,2))*VLOOKUP(MID(G6,7,3),$I$17:$K$21,3,0) -> 1478400 | K6: =H6*(J6+(25%*J6)) -> 7392000 | L6: =IF(K6>=10000000,K6*25%,IF(K6>=8000000,K6*20%,IF(K6>=5000000,K6*15%,IF(K6>=3000000,K6*10%,IF(K6>=2000000,K6*5%,0))))) -> 1108800 | M6: =IF(AND(K6>=5000000,L6>=2000000),"Power Bank",IF(AND(K6>=2000000,L6>=500000),"TWS",IF(AND(K6<2000000,L6<500000),"Voucher","-"))) -> TWS | N6: =K6-L6 -> 6283200
B7: 0.2 | C7: ≥ 8.000.000 | F7: 4 | G7: AC-73-EUR-M4 | H7: 5 | I7: =VLOOKUP(LEFT(G7,2),$F$16:$G$24,2,0)&"-"&HLOOKUP(RIGHT(G7,2),$G$26:$M$27,2,0) -> AC-Panasonic | J7: =VALUE(MID(G7,4,2))*VLOOKUP(MID(G7,7,3),$I$17:$K$21,3,0) -> 1460000 | K7: =H7*(J7+(25%*J7)) -> 9125000 | L7: =IF(K7>=10000000,K7*25%,IF(K7>=8000000,K7*20%,IF(K7>=5000000,K7*15%,IF(K7>=3000000,K7*10%,IF(K7>=2000000,K7*5%,0))))) -> 1825000 | M7: =IF(AND(K7>=5000000,L7>=2000000),"Power Bank",IF(AND(K7>=2000000,L7>=500000),"TWS",IF(AND(K7<2000000,L7<500000),"Voucher","-"))) -> TWS | N7: =K7-L7 -> 7300000
B8: 0.15 | C8: ≥ 5.000.000 | F8: 5 | G8: KL-73-USD-M5 | H8: 3 | I8: =VLOOKUP(LEFT(G8,2),$F$16:$G$24,2,0)&"-"&HLOOKUP(RIGHT(G8,2),$G$26:$M$27,2,0) -> Kulkas-Philips | J8: =VALUE(MID(G8,4,2))*VLOOKUP(MID(G8,7,3),$I$17:$K$21,3,0) -> 1226400 | K8: =H8*(J8+(25%*J8)) -> 4599000 | L8: =IF(K8>=10000000,K8*25%,IF(K8>=8000000,K8*20%,IF(K8>=5000000,K8*15%,IF(K8>=3000000,K8*10%,IF(K8>=2000000,K8*5%,0))))) -> 459900 | M8: =IF(AND(K8>=5000000,L8>=2000000),"Power Bank",IF(AND(K8>=2000000,L8>=500000),"TWS",IF(AND(K8<2000000,L8<500000),"Voucher","-"))) -> - | N8: =K8-L8 -> 4139100
B9: 0.1 | C9: ≥ 3.000.000 | F9: 6 | G9: LP-85-SGD-M3 | H9: 2 | I9: =VLOOKUP(LEFT(G9,2),$F$16:$G$24,2,0)&"-"&HLOOKUP(RIGHT(G9,2),$G$26:$M$27,2,0) -> Laptop-Sony | J9: =VALUE(MID(G9,4,2))*VLOOKUP(MID(G9,7,3),$I$17:$K$21,3,0) -> 1190000 | K9: =H9*(J9+(25%*J9)) -> 2975000 | L9: =IF(K9>=10000000,K9*25%,IF(K9>=8000000,K9*20%,IF(K9>=5000000,K9*15%,IF(K9>=3000000,K9*10%,IF(K9>=2000000,K9*5%,0))))) -> 148750 | M9: =IF(AND(K9>=5000000,L9>=2000000),"Power Bank",IF(AND(K9>=2000000,L9>=500000),"TWS",IF(AND(K9<2000000,L9<500000),"Voucher","-"))) -> - | N9: =K9-L9 -> 2826250
B10: 0.05 | C10: ≥ 2.000.000 | F10: 7 | G10: KL-93-AUD-M6 | H10: 4 | I10: =VLOOKUP(LEFT(G10,2),$F$16:$G$24,2,0)&"-"&HLOOKUP(RIGHT(G10,2),$G$26:$M$27,2,0) -> Kulkas-Sharp | J10: =VALUE(MID(G10,4,2))*VLOOKUP(MID(G10,7,3),$I$17:$K$21,3,0) -> 1116000 | K10: =H10*(J10+(25%*J10)) -> 5580000 | L10: =IF(K10>=10000000,K10*25%,IF(K10>=8000000,K10*20%,IF(K10>=5000000,K10*15%,IF(K10>=3000000,K10*10%,IF(K10>=2000000,K10*5%,0))))) -> 837000 | M10: =IF(AND(K10>=5000000,L10>=2000000),"Power Bank",IF(AND(K10>=2000000,L10>=500000),"TWS",IF(AND(K10<2000000,L10<500000),"Voucher","-"))) -> TWS | N10: =K10-L10 -> 4743000
B11: 0 | C11: < 2.000.000 | F11: 8 | G11: KP-41-AUD-M5 | H11: 1 | I11: =VLOOKUP(LEFT(G11,2),$F$16:$G$24,2,0)&"-"&HLOOKUP(RIGHT(G11,2),$G$26:$M$27,2,0) -> Kipas-Philips | J11: =VALUE(MID(G11,4,2))*VLOOKUP(MID(G11,7,3),$I$17:$K$21,3,0) -> 492000 | K11: =H11*(J11+(25%*J11)) -> 615000 | L11: =IF(K11>=10000000,K11*25%,IF(K11>=8000000,K11*20%,IF(K11>=5000000,K11*15%,IF(K11>=3000000,K11*10%,IF(K11>=2000000,K11*5%,0))))) -> 0 | M11: =IF(AND(K11>=5000000,L11>=2000000),"Power Bank",IF(AND(K11>=2000000,L11>=500000),"TWS",IF(AND(K11<2000000,L11<500000),"Voucher","-"))) -> Voucher | N11: =K11-L11 -> 615000
F12: 9 | G12: MC-84-EUR-M5 | H12: 7 | I12: =VLOOKUP(LEFT(G12,2),$F$16:$G$24,2,0)&"-"&HLOOKUP(RIGHT(G12,2),$G$26:$M$27,2,0) -> Mesin Cuci-Philips | J12: =VALUE(MID(G12,4,2))*VLOOKUP(MID(G12,7,3),$I$17:$K$21,3,0) -> 1680000 | K12: =H12*(J12+(25%*J12)) -> 14700000 | L12: =IF(K12>=10000000,K12*25%,IF(K12>=8000000,K12*20%,IF(K12>=5000000,K12*15%,IF(K12>=3000000,K12*10%,IF(K12>=2000000,K12*5%,0))))) -> 3675000 | M12: =IF(AND(K12>=5000000,L12>=2000000),"Power Bank",IF(AND(K12>=2000000,L12>=500000),"TWS",IF(AND(K12<2000000,L12<500000),"Voucher","-"))) -> Power Bank | N12: =K12-L12 -> 11025000
B13: BONUS | F13: 10 | G13: TB-92-AUD-M1 | H13: 5 | I13: =VLOOKUP(LEFT(G13,2),$F$16:$G$24,2,0)&"-"&HLOOKUP(RIGHT(G13,2),$G$26:$M$27,2,0) -> Tablet-Samsung | J13: =VALUE(MID(G13,4,2))*VLOOKUP(MID(G13,7,3),$I$17:$K$21,3,0) -> 1104000 | K13: =H13*(J13+(25%*J13)) -> 6900000 | L13: =IF(K13>=10000000,K13*25%,IF(K13>=8000000,K13*20%,IF(K13>=5000000,K13*15%,IF(K13>=3000000,K13*10%,IF(K13>=2000000,K13*5%,0))))) -> 1035000 | M13: =IF(AND(K13>=5000000,L13>=2000000),"Power Bank",IF(AND(K13>=2000000,L13>=500000),"TWS",IF(AND(K13<2000000,L13<500000),"Voucher","-"))) -> TWS | N13: =K13-L13 -> 5865000
B14: HARGA JUAL | C14: DISKON | M14: Total seluruh nilai | N14: =SUM(N4:N13) -> 62540300
B15: ≥ 5.000.000 | C15: ≥ 2.000.000 | D15: Power Bank | F15: Kode Barang | G15: Nama Barang | M15: Nilai terbesar | N15: =MIN(N4:N13) -> 615000
B16: ≥ 2.000.000 | C16: ≥ 500.000 | D16: TWS | F16: TV | G16: Televisi | I16: 💵 Rate Mata Uang | M16: Nilai terrendah | N16: =MAX(N4:N13) -> 12993750
B17: < 2.000.000 | C17: < 500.000 | D17: Voucher | F17: KP | G17: Kipas | I17: USD | J17: US Dollar | K17: 16800 | M17: Nilai rata-rata | N17: =AVERAGE(N4:N13) -> 6254030
F18: KL | G18: Kulkas | I18: AUD | J18: Australian Dollar | K18: 12000 | M18: Jumlah Data Barang | N18: =COUNT(N4:N13) -> 10
F19: MC | G19: Mesin Cuci | I19: CAD | J19: Canadian Dollar | K19: 12500
F20: AC | G20: AC | I20: SGD | J20: Singapore Dollar | K20: 14000
F21: HP | G21: Handphone | I21: EUR | J21: Euro | K21: 20000
F22: LP | G22: Laptop
F23: TB | G23: Tablet
F24: SP | G24: Speaker
F26: Kode Merek | G26: M1 | H26: M2 | I26: M3 | J26: M4 | K26: M5 | L26: M6 | M26: M7
F27: Merk | G27: Samsung | H27: LG | I27: Sony | J27: Panasonic | K27: Philips | L27: Sharp | M27: Toshiba

Sheet Sheet5
B3: No | C3: Nama | D3: GOL | E3: Gaji Pokok | F3: Status | G3: Jumlah Anak | H3: Masa Kerja (Tahun) | I3: Tunjangan Anak | J3: Tunjangan Keluarga | K3: Tunjangan Jabatan | L3: Tunjangan Transportasi | N3: GOLONGAN
B4: 1 | C4: Adinia | D4: A | E4: =VLOOKUP(D4,$N$4:$O$6,2,0) -> 1500000 | F4: Menikah | G4: 2 | H4: 5 | I4: =IF(G4=0,0,IF(G4=1,$O$9,$O$10)) -> 600000 | J4: =IF(F4="Menikah",$O$13,$O$14) -> 500000 | K4: =IF(H4>=6,$O$17,$O$18) -> 350000 | L4: =E4*7.5% -> 112500 | N4: A | O4: 1500000
B5: 2 | C5: Bella | D5: B | E5: =VLOOKUP(D5,$N$4:$O$6,2,0) -> 1800000 | F5: Menikah | G5: 3 | H5: 7 | I5: =IF(G5=0,0,IF(G5=1,$O$9,$O$10)) -> 600000 | J5: =IF(F5="Menikah",$O$13,$O$14) -> 500000 | K5: =IF(H5>=6,$O$17,$O$18) -> 1000000 | L5: =E5*7.5% -> 135000 | N5: B | O5: 1800000
B6: 3 | C6: Cecilia | D6: A | E6: =VLOOKUP(D6,$N$4:$O$6,2,0) -> 1500000 | F6: Lajang | G6: 0 | H6: 6 | I6: =IF(G6=0,0,IF(G6=1,$O$9,$O$10)) -> 0 | J6: =IF(F6="Menikah",$O$13,$O$14) -> 400000 | K6: =IF(H6>=6,$O$17,$O$18) -> 1000000 | L6: =E6*7.5% -> 112500 | N6: C | O6: 2000000
B7: 4 | C7: Dewo | D7: B | E7: =VLOOKUP(D7,$N$4:$O$6,2,0) -> 1800000 | F7: Lajang | G7: 0 | H7: 6 | I7: =IF(G7=0,0,IF(G7=1,$O$9,$O$10)) -> 0 | J7: =IF(F7="Menikah",$O$13,$O$14) -> 400000 | K7: =IF(H7>=6,$O$17,$O$18) -> 1000000 | L7: =E7*7.5% -> 135000
B8: 5 | C8: Edo | D8: C | E8: =VLOOKUP(D8,$N$4:$O$6,2,0) -> 2000000 | F8: Lajang | G8: 0 | H8: 5 | I8: =IF(G8=0,0,IF(G8=1,$O$9,$O$10)) -> 0 | J8: =IF(F8="Menikah",$O$13,$O$14) -> 400000 | K8: =IF(H8>=6,$O$17,$O$18) -> 350000 | L8: =E8*7.5% -> 150000 | N8: TUNJANGAN ANAK
B9: 6 | C9: Fakhri | D9: C | E9: =VLOOKUP(D9,$N$4:$O$6,2,0) -> 2000000 | F9: Menikah | G9: 2 | H9: 4 | I9: =IF(G9=0,0,IF(G9=1,$O$9,$O$10)) -> 600000 | J9: =IF(F9="Menikah",$O$13,$O$14) -> 500000 | K9: =IF(H9>=6,$O$17,$O$18) -> 350000 | L9: =E9*7.5% -> 150000 | N9: 1 | O9: 300000
B10: 7 | C10: Ginanjar | D10: A | E10: =VLOOKUP(D10,$N$4:$O$6,2,0) -> 1500000 | F10: Lajang | G10: 0 | H10: 2 | I10: =IF(G10=0,0,IF(G10=1,$O$9,$O$10)) -> 0 | J10: =IF(F10="Menikah",$O$13,$O$14) -> 400000 | K10: =IF(H10>=6,$O$17,$O$18) -> 350000 | L10: =E10*7.5% -> 112500 | N10: ≥ 2 | O10: 600000
B11: 8 | C11: Iddo | D11: B | E11: =VLOOKUP(D11,$N$4:$O$6,2,0) -> 1800000 | F11: Menikah | G11: 4 | H11: 5 | I11: =IF(G11=0,0,IF(G11=1,$O$9,$O$10)) -> 600000 | J11: =IF(F11="Menikah",$O$13,$O$14) -> 500000 | K11: =IF(H11>=6,$O$17,$O$18) -> 350000 | L11: =E11*7.5% -> 135000
B12: 9 | C12: Junne | D12: C | E12: =VLOOKUP(D12,$N$4:$O$6,2,0) -> 2000000 | F12: Menikah | G12: 1 | H12: 2 | I12: =IF(G12=0,0,IF(G12=1,$O$9,$O$10)) -> 300000 | J12: =IF(F12="Menikah",$O$13,$O$14) -> 500000 | K12: =IF(H12>=6,$O$17,$O$18) -> 350000 | L12: =E12*7.5% -> 150000 | N12: TUNJANGAN KELUARGA
N13: MENIKAH | O13: 500000
N14: SINGLE | O14: 400000
N16: TUNJANGAN JABATAN
N17: ≥ 6 TAHUN | O17: 1000000
N18: <6 TAHUN | O18: 350000
N20: TUNJANGAN TRANSPORTASI | O20: 7,5% GP

Sheet Sheet6
B3: NO | C3: NAMA | D3: KODE | E3: LUAS TANAH | F3: HARGA JUAL | G3: BIAYA PPn | H3: TOTAL HARGA JUAL | I3: LAMA BULAN | J3: UANG MUKA | K3: ANGSURAN PERBULAN | L3: BUNGA Per BULAN | M3: SETORAN PER BULAN | N3: TOTAL HARGA KREDIT | O3: TANGGAL MULAI | P3: TANGGAL BERAKHIR
B4: 1 | C4: Leni | D4: M | E4: =VLOOKUP(D4,$R$11:$U$15,2,0) -> 100 | F4: =VLOOKUP(D4,$R$11:$U$15,3,0) -> 210000000 | G4: =F4*VLOOKUP(D4,$R$11:$U$15,4,0) -> 6300000 | H4: =F4+G4 -> 216300000 | I4: 120 | J4: =H4*HLOOKUP(D4,$S$5:$W$7,2,0) -> 32445000 | K4: =H4*HLOOKUP(D4,$S$5:$W$7,2,0) -> 32445000 | L4: =(H4-J4)/I4 -> 1532125 | M4: =K4*HLOOKUP(D4,$S$5:$W$7,3,0) -> 973350 | N4: =K4+L4 -> 33977125 | O4: 44575 | P4: =EDATE(O4,I4) -> 48227 | R4: Table Kredit
B5: 2 | C5: Indri | D5: T | E5: =VLOOKUP(D5,$R$11:$U$15,2,0) -> 200 | F5: =VLOOKUP(D5,$R$11:$U$15,3,0) -> 350000000 | G5: =F5*VLOOKUP(D5,$R$11:$U$15,4,0) -> 12250000 | H5: =F5+G5 -> 362250000 | I5: 60 | J5: =H5*HLOOKUP(D5,$S$5:$W$7,2,0) -> 90562500 | K5: =H5*HLOOKUP(D5,$S$5:$W$7,2,0) -> 90562500 | L5: =(H5-J5)/I5 -> 4528125 | M5: =K5*HLOOKUP(D5,$S$5:$W$7,3,0) -> 4528125 | N5: =K5+L5 -> 95090625 | O5: 44585 | P5: =EDATE(O5,I5) -> 46411 | R5: Kode | S5: A | T5: C | U5: M | V5: S | W5: T
B6: 3 | C6: Susi | D6: A | E6: =VLOOKUP(D6,$R$11:$U$15,2,0) -> 60 | F6: =VLOOKUP(D6,$R$11:$U$15,3,0) -> 160000000 | G6: =F6*VLOOKUP(D6,$R$11:$U$15,4,0) -> 4000000 | H6: =F6+G6 -> 164000000 | I6: 180 | J6: =H6*HLOOKUP(D6,$S$5:$W$7,2,0) -> 8200000 | K6: =H6*HLOOKUP(D6,$S$5:$W$7,2,0) -> 8200000 | L6: =(H6-J6)/I6 -> 865555.56 | M6: =K6*HLOOKUP(D6,$S$5:$W$7,3,0) -> 82000 | N6: =K6+L6 -> 9065555.6 | O6: 44632 | P6: =EDATE(O6,I6) -> 50111 | R6: Uang Muka | S6: 0.05 | T6: 0.1 | U6: 0.15 | V6: 0.2 | W6: 0.25
B7: 4 | C7: Hendra | D7: S | E7: =VLOOKUP(D7,$R$11:$U$15,2,0) -> 150 | F7: =VLOOKUP(D7,$R$11:$U$15,3,0) -> 250000000 | G7: =F7*VLOOKUP(D7,$R$11:$U$15,4,0) -> 8750000 | H7: =F7+G7 -> 258750000 | I7: 132 | J7: =H7*HLOOKUP(D7,$S$5:$W$7,2,0) -> 51750000 | K7: =H7*HLOOKUP(D7,$S$5:$W$7,2,0) -> 51750000 | L7: =(H7-J7)/I7 -> 1568181.8 | M7: =K7*HLOOKUP(D7,$S$5:$W$7,3,0) -> 2070000 | N7: =K7+L7 -> 53318182 | O7: 44614 | P7: =EDATE(O7,I7) -> 48632 | R7: Bunga | S7: 0.01 | T7: 0.02 | U7: 0.03 | V7: 0.04 | W7: 0.05
B8: 5 | C8: Silvia | D8: C | E8: =VLOOKUP(D8,$R$11:$U$15,2,0) -> 80 | F8: =VLOOKUP(D8,$R$11:$U$15,3,0) -> 190000000 | G8: =F8*VLOOKUP(D8,$R$11:$U$15,4,0) -> 4750000 | H8: =F8+G8 -> 194750000 | I8: 156 | J8: =H8*HLOOKUP(D8,$S$5:$W$7,2,0) -> 19475000 | K8: =H8*HLOOKUP(D8,$S$5:$W$7,2,0) -> 19475000 | L8: =(H8-J8)/I8 -> 1123557.7 | M8: =K8*HLOOKUP(D8,$S$5:$W$7,3,0) -> 389500 | N8: =K8+L8 -> 20598558 | O8: 44678 | P8: =EDATE(O8,I8) -> 49426
B9: 6 | C9: Lina | D9: M | E9: =VLOOKUP(D9,$R$11:$U$15,2,0) -> 100 | F9: =VLOOKUP(D9,$R$11:$U$15,3,0) -> 210000000 | G9: =F9*VLOOKUP(D9,$R$11:$U$15,4,0) -> 6300000 | H9: =F9+G9 -> 216300000 | I9: 144 | J9: =H9*HLOOKUP(D9,$S$5:$W$7,2,0) -> 32445000 | K9: =H9*HLOOKUP(D9,$S$5:$W$7,2,0) -> 32445000 | L9: =(H9-J9)/I9 -> 1276770.8 | M9: =K9*HLOOKUP(D9,$S$5:$W$7,3,0) -> 973350 | N9: =K9+L9 -> 33721771 | O9: 44681 | P9: =EDATE(O9,I9) -> 49064 | R9: Table Rumah
B10: 7 | C10: Sarah | D10: A | E10: =VLOOKUP(D10,$R$11:$U$15,2,0) -> 60 | F10: =VLOOKUP(D10,$R$11:$U$15,3,0) -> 160000000 | G10: =F10*VLOOKUP(D10,$R$11:$U$15,4,0) -> 4000000 | H10: =F10+G10 -> 164000000 | I10: 48 | J10: =H10*HLOOKUP(D10,$S$5:$W$7,2,0) -> 8200000 | K10: =H10*HLOOKUP(D10,$S$5:$W$7,2,0) -> 8200000 | L10: =(H10-J10)/I10 -> 3245833.3 | M10: =K10*HLOOKUP(D10,$S$5:$W$7,3,0) -> 82000 | N10: =K10+L10 -> 11445833 | O10: 44732 | P10: =EDATE(O10,I10) -> 46193 | R10: Kode | S10: Luas Tanah | T10: Harga Jual | U10: Biaya PPn
B11: 8 | C11: Erdian | D11: C | E11: =VLOOKUP(D11,$R$11:$U$15,2,0) -> 80 | F11: =VLOOKUP(D11,$R$11:$U$15,3,0) -> 190000000 | G11: =F11*VLOOKUP(D11,$R$11:$U$15,4,0) -> 4750000 | H11: =F11+G11 -> 194750000 | I11: 96 | J11: =H11*HLOOKUP(D11,$S$5:$W$7,2,0) -> 19475000 | K11: =H11*HLOOKUP(D11,$S$5:$W$7,2,0) -> 19475000 | L11: =(H11-J11)/I11 -> 1825781.2 | M11: =K11*HLOOKUP(D11,$S$5:$W$7,3,0) -> 389500 | N11: =K11+L11 -> 21300781 | O11: 44747 | P11: =EDATE(O11,I11) -> 47669 | R11: A | S11: 60 | T11: 160000000 | U11: 0.025
B12: 9 | C12: Novi | D12: T | E12: =VLOOKUP(D12,$R$11:$U$15,2,0) -> 200 | F12: =VLOOKUP(D12,$R$11:$U$15,3,0) -> 350000000 | G12: =F12*VLOOKUP(D12,$R$11:$U$15,4,0) -> 12250000 | H12: =F12+G12 -> 362250000 | I12: 168 | J12: =H12*HLOOKUP(D12,$S$5:$W$7,2,0) -> 90562500 | K12: =H12*HLOOKUP(D12,$S$5:$W$7,2,0) -> 90562500 | L12: =(H12-J12)/I12 -> 1617187.5 | M12: =K12*HLOOKUP(D12,$S$5:$W$7,3,0) -> 4528125 | N12: =K12+L12 -> 92179688 | O12: 44801 | P12: =EDATE(O12,I12) -> 49915 | R12: C | S12: 80 | T12: 190000000 | U12: 0.025
B13: 10 | C13: Setiadi | D13: S | E13: =VLOOKUP(D13,$R$11:$U$15,2,0) -> 150 | F13: =VLOOKUP(D13,$R$11:$U$15,3,0) -> 250000000 | G13: =F13*VLOOKUP(D13,$R$11:$U$15,4,0) -> 8750000 | H13: =F13+G13 -> 258750000 | I13: 108 | J13: =H13*HLOOKUP(D13,$S$5:$W$7,2,0) -> 51750000 | K13: =H13*HLOOKUP(D13,$S$5:$W$7,2,0) -> 51750000 | L13: =(H13-J13)/I13 -> 1916666.7 | M13: =K13*HLOOKUP(D13,$S$5:$W$7,3,0) -> 2070000 | N13: =K13+L13 -> 53666667 | O13: 44809 | P13: =EDATE(O13,I13) -> 48096 | R13: M | S13: 100 | T13: 210000000 | U13: 0.03
R14: S | S14: 150 | T14: 250000000 | U14: 0.035
R15: T | S15: 200 | T15: 350000000 | U15: 0.035

Sheet Sheet7
B2: No | C2: Pesanan 1 | D2: Pesanan 2 | E2: Pesanan Batal | F2: Harga Jual | G2: Modal | H2: Jumlah Pesanan | I2: Pesanan OK | J2: Total Harga | K2: % Batal | L2: Pajak 5% | M2: Pesanan 2x | N2: Harga Setelah Diskon (-25% Off) | O2: Total Keuntungan
B3: #1 | C3: 13 | D3: 4 | E3: 7 | F3: 7000 | G3: 6000 | H3: =C3+D3 -> 17 | I3: =H3-E3 -> 10 | J3: =I3*F3 -> 70000 | K3: =E3/H3 -> 0.41176471 | L3: =J3*5% -> 3500 | M3: =H3^2 -> 289 | N3: =J3-(J3*25%) -> 52500 | O3: =(N3-(I3*G3))-L3 -> -11000
B4: #2 | C4: 7 | D4: 10 | E4: 6 | F4: 7000 | G4: 5500 | H4: =C4+D4 -> 17 | I4: =H4-E4 -> 11 | J4: =I4*F4 -> 77000 | K4: =E4/H4 -> 0.35294118 | L4: =J4*5% -> 3850 | M4: =H4^2 -> 289 | N4: =J4-(J4*25%) -> 57750 | O4: =(N4-(I4*G4))-L4 -> -6600
B5: #3 | C5: 7 | D5: 11 | E5: 5 | F5: 7000 | G5: 5600 | H5: =C5+D5 -> 18 | I5: =H5-E5 -> 13 | J5: =I5*F5 -> 91000 | K5: =E5/H5 -> 0.27777778 | L5: =J5*5% -> 4550 | M5: =H5^2 -> 324 | N5: =J5-(J5*25%) -> 68250 | O5: =(N5-(I5*G5))-L5 -> -9100
B6: #4 | C6: 11 | D6: 9 | E6: 6 | F6: 4000 | G6: 3100 | H6: =C6+D6 -> 20 | I6: =H6-E6 -> 14 | J6: =I6*F6 -> 56000 | K6: =E6/H6 -> 0.3 | L6: =J6*5% -> 2800 | M6: =H6^2 -> 400 | N6: =J6-(J6*25%) -> 42000 | O6: =(N6-(I6*G6))-L6 -> -4200
B7: #5 | C7: 10 | D7: 11 | E7: 1 | F7: 9000 | G7: 8000 | H7: =C7+D7 -> 21 | I7: =H7-E7 -> 20 | J7: =I7*F7 -> 180000 | K7: =E7/H7 -> 0.047619048 | L7: =J7*5% -> 9000 | M7: =H7^2 -> 441 | N7: =J7-(J7*25%) -> 135000 | O7: =(N7-(I7*G7))-L7 -> -34000
B8: #6 | C8: 15 | D8: 9 | E8: 7 | F8: 2000 | G8: 1000 | H8: =C8+D8 -> 24 | I8: =H8-E8 -> 17 | J8: =I8*F8 -> 34000 | K8: =E8/H8 -> 0.29166667 | L8: =J8*5% -> 1700 | M8: =H8^2 -> 576 | N8: =J8-(J8*25%) -> 25500 | O8: =(N8-(I8*G8))-L8 -> 6800
B9: #7 | C9: 9 | D9: 7 | E9: 2 | F9: 8000 | G9: 6800 | H9: =C9+D9 -> 16 | I9: =H9-E9 -> 14 | J9: =I9*F9 -> 112000 | K9: =E9/H9 -> 0.125 | L9: =J9*5% -> 5600 | M9: =H9^2 -> 256 | N9: =J9-(J9*25%) -> 84000 | O9: =(N9-(I9*G9))-L9 -> -16800
B10: #8 | C10: 18 | D10: 4 | E10: 4 | F10: 8000 | G10: 6600 | H10: =C10+D10 -> 22 | I10: =H10-E10 -> 18 | J10: =I10*F10 -> 144000 | K10: =E10/H10 -> 0.18181818 | L10: =J10*5% -> 7200 | M10: =H10^2 -> 484 | N10: =J10-(J10*25%) -> 108000 | O10: =(N10-(I10*G10))-L10 -> -18000
B11: #9 | C11: 10 | D11: 11 | E11: 3 | F11: 6000 | G11: 5200 | H11: =C11+D11 -> 21 | I11: =H11-E11 -> 18 | J11: =I11*F11 -> 108000 | K11: =E11/H11 -> 0.14285714 | L11: =J11*5% -> 5400 | M11: =H11^2 -> 441 | N11: =J11-(J11*25%) -> 81000 | O11: =(N11-(I11*G11))-L11 -> -18000
B12: #10 | C12: 8 | D12: 6 | E12: 3 | F12: 5000 | G12: 3700 | H12: =C12+D12 -> 14 | I12: =H12-E12 -> 11 | J12: =I12*F12 -> 55000 | K12: =E12/H12 -> 0.21428571 | L12: =J12*5% -> 2750 | M12: =H12^2 -> 196 | N12: =J12-(J12*25%) -> 41250 | O12: =(N12-(I12*G12))-L12 -> -2200
B13: #11 | C13: 17 | D13: 6 | E13: 9 | F13: 5000 | G13: 4000 | H13: =C13+D13 -> 23 | I13: =H13-E13 -> 14 | J13: =I13*F13 -> 70000 | K13: =E13/H13 -> 0.39130435 | L13: =J13*5% -> 3500 | M13: =H13^2 -> 529 | N13: =J13-(J13*25%) -> 52500 | O13: =(N13-(I13*G13))-L13 -> -7000
B14: #12 | C14: 4 | D14: 7 | E14: 6 | F14: 7000 | G14: 5900 | H14: =C14+D14 -> 11 | I14: =H14-E14 -> 5 | J14: =I14*F14 -> 35000 | K14: =E14/H14 -> 0.54545455 | L14: =J14*5% -> 1750 | M14: =H14^2 -> 121 | N14: =J14-(J14*25%) -> 26250 | O14: =(N14-(I14*G14))-L14 -> -5000
... B16: #14 | C16: 15 | D16: 3 | E16: 6 | F16: 4000 | G16: 3100 | H16: =C16+D16 -> 18 | I16: =H16-E16 -> 12 | J16: =I16*F16 -> 48000 | K16: =E16/H16 -> 0.33333333 | L16: =J16*5% -> 2400 | M16: =H16^2 -> 324 | N16: =J16-(J16*25%) -> 36000 | O16: =(N16-(I16*G16))-L16 -> -3600

Sheet Sheet8
B2: NO | C2: PENDIDIKAN | D2: NAMA PEGAWAI | E2: SANKSI | G2: GAJI (Rp.) | J2: TOTAL GAJI (Rp.) | K2: PAJAK (%) | L2: GAJI SETELAH PAJAK (Rp.) | M2: POT. DISIPLIN (Rp.) | N2: POT. WAKTU KERJA (Rp.) | O2: GAJI BERSIH (Rp.)
E3: DIS | F3: JAM | G3: POKOK | H3: TUNJANGAN | I3: UANG MAKAN
B4: Contoh | C4: S-1 | D4: Andi Setiadi | E4: R | F4: T2 | G4: 3500000 | H4: 1650000 | I4: 350000 | J4: 5500000 | K4: 0.04 | L4: 5280000 | M4: 825000 | N4: 275000 | O4: 4180000 | Q4: 1 BULAN
Q5: 25 HARI KERJA
B6: 1 | C6: D-III | D6: Gina Utami Andi | E6: N | F6: T5 | G6: =VLOOKUP(C6,Sheet8.1!$F$4:$I$7,2,0) -> 3200000 | H6: =VLOOKUP(C6,Sheet8.1!$F$4:$I$7,3,0) -> 1350000 | I6: =VLOOKUP(C6,Sheet8.1!$F$4:$I$7,4,0)*25 -> 325000 | J6: =SUM(G6:I6) -> 4875000 | K6: =HLOOKUP(C6,Sheet8.1!$G$11:$J$12,2,0) -> 0.03 | L6: =J6-(J6*K6) -> 4728750 | M6: =J6*VLOOKUP(E6,Sheet8.1!$C$4:$D$7,2,0) -> 0 | N6: =J6*INDEX(Sheet8.1!$C$12:$C$16,MATCH(F6,Sheet8.1!$D$12:$D$16,0)) -> 1218750 | O6: =L6-M6-N6 -> 3510000
B7: 2 | C7: S-1 | D7: Agung Perkasa | E7: N | F7: T2 | G7: =VLOOKUP(C7,Sheet8.1!$F$4:$I$7,2,0) -> 3500000 | H7: =VLOOKUP(C7,Sheet8.1!$F$4:$I$7,3,0) -> 1650000 | I7: =VLOOKUP(C7,Sheet8.1!$F$4:$I$7,4,0)*25 -> 350000 | J7: =SUM(G7:I7) -> 5500000 | K7: =HLOOKUP(C7,Sheet8.1!$G$11:$J$12,2,0) -> 0.04 | L7: =J7-(J7*K7) -> 5280000 | M7: =J7*VLOOKUP(E7,Sheet8.1!$C$4:$D$7,2,0) -> 0 | N7: =J7*INDEX(Sheet8.1!$C$12:$C$16,MATCH(F7,Sheet8.1!$D$12:$D$16,0)) -> 275000 | O7: =L7-M7-N7 -> 5005000
B8: 3 | C8: SMA | D8: Kaludin amat | E8: R | F8: T5 | G8: =VLOOKUP(C8,Sheet8.1!$F$4:$I$7,2,0) -> 3000000 | H8: =VLOOKUP(C8,Sheet8.1!$F$4:$I$7,3,0) -> 1150000 | I8: =VLOOKUP(C8,Sheet8.1!$F$4:$I$7,4,0)*25 -> 300000 | J8: =SUM(G8:I8) -> 4450000 | K8: =HLOOKUP(C8,Sheet8.1!$G$11:$J$12,2,0) -> 0.02 | L8: =J8-(J8*K8) -> 4361000 | M8: =J8*VLOOKUP(E8,Sheet8.1!$C$4:$D$7,2,0) -> 667500 | N8: =J8*INDEX(Sheet8.1!$C$12:$C$16,MATCH(F8,Sheet8.1!$D$12:$D$16,0)) -> 1112500 | O8: =L8-M8-N8 -> 2581000
B9: 4 | C9: S-2 | D9: Lina Syahputra Joko | E9: N | F9: T1 | G9: =VLOOKUP(C9,Sheet8.1!$F$4:$I$7,2,0) -> 3850000 | H9: =VLOOKUP(C9,Sheet8.1!$F$4:$I$7,3,0) -> 1850000 | I9: =VLOOKUP(C9,Sheet8.1!$F$4:$I$7,4,0)*25 -> 375000 | J9: =SUM(G9:I9) -> 6075000 | K9: =HLOOKUP(C9,Sheet8.1!$G$11:$J$12,2,0) -> 0.05 | L9: =J9-(J9*K9) -> 5771250 | M9: =J9*VLOOKUP(E9,Sheet8.1!$C$4:$D$7,2,0) -> 0 | N9: =J9*INDEX(Sheet8.1!$C$12:$C$16,MATCH(F9,Sheet8.1!$D$12:$D$16,0)) -> 0 | O9: =L9-M9-N9 -> 5771250
B10: 5 | C10: S-1 | D10: Kiki Fajar Eka | E10: B | F10: T4 | G10: =VLOOKUP(C10,Sheet8.1!$F$4:$I$7,2,0) -> 3500000 | H10: =VLOOKUP(C10,Sheet8.1!$F$4:$I$7,3,0) -> 1650000 | I10: =VLOOKUP(C10,Sheet8.1!$F$4:$I$7,4,0)*25 -> 350000 | J10: =SUM(G10:I10) -> 5500000 | K10: =HLOOKUP(C10,Sheet8.1!$G$11:$J$12,2,0) -> 0.04 | L10: =J10-(J10*K10) -> 5280000 | M10: =J10*VLOOKUP(E10,Sheet8.1!$C$4:$D$7,2,0) -> 2750000 | N10: =J10*INDEX(Sheet8.1!$C$12:$C$16,MATCH(F10,Sheet8.1!$D$12:$D$16,0)) -> 825000 | O10: =L10-M10-N10 -> 1705000
B11: 6 | C11: SMA | D11: Gina Anggraini Halim | E11: N | F11: T1 | G11: =VLOOKUP(C11,Sheet8.1!$F$4:$I$7,2,0) -> 3000000 | H11: =VLOOKUP(C11,Sheet8.1!$F$4:$I$7,3,0) -> 1150000 | I11: =VLOOKUP(C11,Sheet8.1!$F$4:$I$7,4,0)*25 -> 300000 | J11: =SUM(G11:I11) -> 4450000 | K11: =HLOOKUP(C11,Sheet8.1!$G$11:$J$12,2,0) -> 0.02 | L11: =J11-(J11*K11) -> 4361000 | M11: =J11*VLOOKUP(E11,Sheet8.1!$C$4:$D$7,2,0) -> 0 | N11: =J11*INDEX(Sheet8.1!$C$12:$C$16,MATCH(F11,Sheet8.1!$D$12:$D$16,0)) -> 0 | O11: =L11-M11-N11 -> 4361000
B12: 7 | C12: S-1 | D12: Wibowo Rian Hartono | E12: N | F12: T3 | G12: =VLOOKUP(C12,Sheet8.1!$F$4:$I$7,2,0) -> 3500000 | H12: =VLOOKUP(C12,Sheet8.1!$F$4:$I$7,3,0) -> 1650000 | I12: =VLOOKUP(C12,Sheet8.1!$F$4:$I$7,4,0)*25 -> 350000 | J12: =SUM(G12:I12) -> 5500000 | K12: =HLOOKUP(C12,Sheet8.1!$G$11:$J$12,2,0) -> 0.04 | L12: =J12-(J12*K12) -> 5280000 | M12: =J12*VLOOKUP(E12,Sheet8.1!$C$4:$D$7,2,0) -> 0 | N12: =J12*INDEX(Sheet8.1!$C$12:$C$16,MATCH(F12,Sheet8.1!$D$12:$D$16,0)) -> 550000 | O12: =L12-M12-N12 -> 4730000
B13: 8 | C13: S-2 | D13: Putri Tono | E13: S | F13: T2 | G13: =VLOOKUP(C13,Sheet8.1!$F$4:$I$7,2,0) -> 3850000 | H13: =VLOOKUP(C13,Sheet8.1!$F$4:$I$7,3,0) -> 1850000 | I13: =VLOOKUP(C13,Sheet8.1!$F$4:$I$7,4,0)*25 -> 375000 | J13: =SUM(G13:I13) -> 6075000 | K13: =HLOOKUP(C13,Sheet8.1!$G$11:$J$12,2,0) -> 0.05 | L13: =J13-(J13*K13) -> 5771250 | M13: =J13*VLOOKUP(E13,Sheet8.1!$C$4:$D$7,2,0) -> 1518750 | N13: =J13*INDEX(Sheet8.1!$C$12:$C$16,MATCH(F13,Sheet8.1!$D$12:$D$16,0)) -> 303750 | O13: =L13-M13-N13 -> 3948750
B14: 9 | C14: S-2 | D14: Oka Halim Syahputra | E14: N | F14: T1 | G14: =VLOOKUP(C14,Sheet8.1!$F$4:$I$7,2,0) -> 3850000 | H14: =VLOOKUP(C14,Sheet8.1!$F$4:$I$7,3,0) -> 1850000 | I14: =VLOOKUP(C14,Sheet8.1!$F$4:$I$7,4,0)*25 -> 375000 | J14: =SUM(G14:I14) -> 6075000 | K14: =HLOOKUP(C14,Sheet8.1!$G$11:$J$12,2,0) -> 0.05 | L14: =J14-(J14*K14) -> 5771250 | M14: =J14*VLOOKUP(E14,Sheet8.1!$C$4:$D$7,2,0) -> 0 | N14: =J14*INDEX(Sheet8.1!$C$12:$C$16,MATCH(F14,Sheet8.1!$D$12:$D$16,0)) -> 0 | O14: =L14-M14-N14 -> 5771250
B15: 10 | C15: S-2 | D15: Fajar Lina Syahputra | E15: R | F15: T2 | G15: =VLOOKUP(C15,Sheet8.1!$F$4:$I$7,2,0) -> 3850000 | H15: =VLOOKUP(C15,Sheet8.1!$F$4:$I$7,3,0) -> 1850000 | I15: =VLOOKUP(C15,Sheet8.1!$F$4:$I$7,4,0)*25 -> 375000 | J15: =SUM(G15:I15) -> 6075000 | K15: =HLOOKUP(C15,Sheet8.1!$G$11:$J$12,2,0) -> 0.05 | L15: =J15-(J15*K15) -> 5771250 | M15: =J15*VLOOKUP(E15,Sheet8.1!$C$4:$D$7,2,0) -> 911250 | N15: =J15*INDEX(Sheet8.1!$C$12:$C$16,MATCH(F15,Sheet8.1!$D$12:$D$16,0)) -> 303750 | O15: =L15-M15-N15 -> 4556250
B16: 11 | C16: SMA | D16: Kiki Permata Eka | E16: R | F16: T1 | G16: =VLOOKUP(C16,Sheet8.1!$F$4:$I$7,2,0) -> 3000000 | H16: =VLOOKUP(C16,Sheet8.1!$F$4:$I$7,3,0) -> 1150000 | I16: =VLOOKUP(C16,Sheet8.1!$F$4:$I$7,4,0)*25 -> 300000 | J16: =SUM(G16:I16) -> 4450000 | K16: =HLOOKUP(C16,Sheet8.1!$G$11:$J$12,2,0) -> 0.02 | L16: =J16-(J16*K16) -> 4361000 | M16: =J16*VLOOKUP(E16,Sheet8.1!$C$4:$D$7,2,0) -> 667500 | N16: =J16*INDEX(Sheet8.1!$C$12:$C$16,MATCH(F16,Sheet8.1!$D$12:$D$16,0)) -> 0 | O16: =L16-M16-N16 -> 3693500
B17: 12 | C17: S-1 | D17: Sawidi Aisah | E17: S | F17: T3 | G17: =VLOOKUP(C17,Sheet8.1!$F$4:$I$7,2,0) -> 3500000 | H17: =VLOOKUP(C17,Sheet8.1!$F$4:$I$7,3,0) -> 1650000 | I17: =VLOOKUP(C17,Sheet8.1!$F$4:$I$7,4,0)*25 -> 350000 | J17: =SUM(G17:I17) -> 5500000 | K17: =HLOOKUP(C17,Sheet8.1!$G$11:$J$12,2,0) -> 0.04 | L17: =J17-(J17*K17) -> 5280000 | M17: =J17*VLOOKUP(E17,Sheet8.1!$C$4:$D$7,2,0) -> 1375000 | N17: =J17*INDEX(Sheet8.1!$C$12:$C$16,MATCH(F17,Sheet8.1!$D$12:$D$16,0)) -> 550000 | O17: =L17-M17-N17 -> 3355000
... B28: 23 | C28: S-1 | D28: Mira Hartono | E28: N | F28: T1 | G28: =VLOOKUP(C28,Sheet8.1!$F$4:$I$7,2,0) -> 3500000 | H28: =VLOOKUP(C28,Sheet8.1!$F$4:$I$7,3,0) -> 1650000 | I28: =VLOOKUP(C28,Sheet8.1!$F$4:$I$7,4,0)*25 -> 350000 | J28: =SUM(G28:I28) -> 5500000 | K28: =HLOOKUP(C28,Sheet8.1!$G$11:$J$12,2,0) -> 0.04 | L28: =J28-(J28*K28) -> 5280000 | M28: =J28*VLOOKUP(E28,Sheet8.1!$C$4:$D$7,2,0) -> 0 | N28: =J28*INDEX(Sheet8.1!$C$12:$C$16,MATCH(F28,Sheet8.1!$D$12:$D$16,0)) -> 0 | O28: =L28-M28-N28 -> 5280000
C29: 10 | D29: TOTAL | G29: =SUM(G6:G28) -> 79350000 | H29: =SUM(H6:H28) -> 35750000 | I29: =SUM(I6:I28) -> 7875000 | J29: =SUM(J6:J28) -> 122975000 | K29: =AVERAGE(K6:K28) -> 0.036956522 | L29: =SUM(L6:L28) -> 118262250 | M29: =SUM(M6:M28) -> 13795000 | N29: =SUM(N6:N28) -> 9383750 | O29: =SUM(O6:O28) -> 95083500

Sheet Sheet8.1
B2: T. POTONGAN HUKUMAN | F2: TABEL GAJI (Rp.)
B3: DISIPLIN | C3: KET | D3: POTONGAN | F3: PENDIDIKAN | G3: POKOK | H3: TUNJANGAN | I3: UANG MAKAN / HARI
B4: Berat | C4: B | D4: 0.5 | F4: SMA | G4: 3000000 | H4: 1150000 | I4: 12000
B5: Sedang | C5: S | D5: 0.25 | F5: D-III | G5: 3200000 | H5: 1350000 | I5: 13000
B6: Ringan | C6: R | D6: 0.15 | F6: S-1 | G6: 3500000 | H6: 1650000 | I6: 14000
B7: Nihil | C7: N | D7: 0 | F7: S-2 | G7: 3850000 | H7: 1850000 | I7: 15000
B10: T. POTONGAN WAKTU KERJA | F10: TABEL PAJAK
B11: MENIT | C11: POT | D11: KET | F11: PENDIDIKAN | G11: SMA | H11: D-III | I11: S-1 | J11: S-2
B12: 0' | C12: 0 | D12: T1 | F12: PAJAK | G12: 0.02 | H12: 0.03 | I12: 0.04 | J12: 0.05
B13: 1' - 60' | C13: 0.05 | D13: T2
B14: 61' - 120' | C14: 0.1 | D14: T3
B15: 121' - 240' | C15: 0.15 | D15: T4
B16: 241' Keatas | C16: 0.25 | D16: T5

Sheet Sheet9
F2: 1 | H2: 2 | J2: 3 | K2: 4 | L2: 5 | M2: 6
B3: NO. | D3: TANGGAL | E3: KODE PELANGGAN | F3: NAMA PELANGGAN | G3: KODE PRODUK | H3: NAMA PRODUK | I3: QTY | J3: HARGA SATUAN | K3: TOTAL PENJUALAN | L3: DISKON | M3: PENJUALAN BERSIH
B4: Contoh | D4: 1-Nov | E4: BK-02 | F4: Toko Beni Kusuma | G4: B-10 | H4: Besi 10 Meter | I4: 350 | J4: 425000 | K4: 148750000 | L4: 0.1 | M4: 133875000 | O4: Kode Pelanggan
B6: 1 | D6: 1-Nov | E6: AB-01 | F6: =VLOOKUP(E6,$O$7:$P$9,2,0) -> Toko Ahmad Budiman | G6: B-05 | H6: =HLOOKUP(G6,$P$12:$S$13,2,0) -> Besi 5 Meter | I6: 240 | J6: =HLOOKUP(G6,$P$12:$S$14,3,0) -> 250000 | K6: =I6*J6 -> 60000000 | L6: =IF(K6>=100000000,10%,IF(K6>=50000000,5%,0)) -> 0.05 | M6: =K6-(K6*L6) -> 57000000 | O6: KODE | P6: NAMA PELANGGAN
B7: 2 | D7: 1-Nov | E7: BK-02 | F7: =VLOOKUP(E7,$O$7:$P$9,2,0) -> Toko Beni Kusuma | G7: B-10 | H7: =HLOOKUP(G7,$P$12:$S$13,2,0) -> Besi 10 Meter | I7: 350 | J7: =HLOOKUP(G7,$P$12:$S$14,3,0) -> 425000 | K7: =I7*J7 -> 148750000 | L7: =IF(K7>=100000000,10%,IF(K7>=50000000,5%,0)) -> 0.1 | M7: =K7-(K7*L7) -> 133875000 | O7: AB-01 | P7: Toko Ahmad Budiman
B8: 3 | D8: 1-Nov | E8: CJ-03 | F8: =VLOOKUP(E8,$O$7:$P$9,2,0) -> Toko Chris John | G8: P-05 | H8: =HLOOKUP(G8,$P$12:$S$13,2,0) -> Pipa 5 Meter | I8: 130 | J8: =HLOOKUP(G8,$P$12:$S$14,3,0) -> 78000 | K8: =I8*J8 -> 10140000 | L8: =IF(K8>=100000000,10%,IF(K8>=50000000,5%,0)) -> 0 | M8: =K8-(K8*L8) -> 10140000 | O8: BK-02 | P8: Toko Beni Kusuma
B9: 4 | D9: 2-Nov | E9: CJ-03 | F9: =VLOOKUP(E9,$O$7:$P$9,2,0) -> Toko Chris John | G9: P-10 | H9: =HLOOKUP(G9,$P$12:$S$13,2,0) -> Pipa 10 Meter | I9: 560 | J9: =HLOOKUP(G9,$P$12:$S$14,3,0) -> 140000 | K9: =I9*J9 -> 78400000 | L9: =IF(K9>=100000000,10%,IF(K9>=50000000,5%,0)) -> 0.05 | M9: =K9-(K9*L9) -> 74480000 | O9: CJ-03 | P9: Toko Chris John
B10: 5 | D10: 2-Nov | E10: BK-02 | F10: =VLOOKUP(E10,$O$7:$P$9,2,0) -> Toko Beni Kusuma | G10: B-05 | H10: =HLOOKUP(G10,$P$12:$S$13,2,0) -> Besi 5 Meter | I10: 780 | J10: =HLOOKUP(G10,$P$12:$S$14,3,0) -> 250000 | K10: =I10*J10 -> 195000000 | L10: =IF(K10>=100000000,10%,IF(K10>=50000000,5%,0)) -> 0.1 | M10: =K10-(K10*L10) -> 175500000
B11: 6 | D11: 2-Nov | E11: AB-01 | F11: =VLOOKUP(E11,$O$7:$P$9,2,0) -> Toko Ahmad Budiman | G11: B-10 | H11: =HLOOKUP(G11,$P$12:$S$13,2,0) -> Besi 10 Meter | I11: 890 | J11: =HLOOKUP(G11,$P$12:$S$14,3,0) -> 425000 | K11: =I11*J11 -> 378250000 | L11: =IF(K11>=100000000,10%,IF(K11>=50000000,5%,0)) -> 0.1 | M11: =K11-(K11*L11) -> 340425000 | O11: Kode Produk
B12: 7 | D12: 2-Nov | E12: BK-02 | F12: =VLOOKUP(E12,$O$7:$P$9,2,0) -> Toko Beni Kusuma | G12: P-05 | H12: =HLOOKUP(G12,$P$12:$S$13,2,0) -> Pipa 5 Meter | I12: 420 | J12: =HLOOKUP(G12,$P$12:$S$14,3,0) -> 78000 | K12: =I12*J12 -> 32760000 | L12: =IF(K12>=100000000,10%,IF(K12>=50000000,5%,0)) -> 0 | M12: =K12-(K12*L12) -> 32760000 | O12: KODE | P12: B-05 | Q12: B-10 | R12: P-05 | S12: P-10
B13: 8 | D13: 2-Nov | E13: AB-01 | F13: =VLOOKUP(E13,$O$7:$P$9,2,0) -> Toko Ahmad Budiman | G13: P-10 | H13: =HLOOKUP(G13,$P$12:$S$13,2,0) -> Pipa 10 Meter | I13: 110 | J13: =HLOOKUP(G13,$P$12:$S$14,3,0) -> 140000 | K13: =I13*J13 -> 15400000 | L13: =IF(K13>=100000000,10%,IF(K13>=50000000,5%,0)) -> 0 | M13: =K13-(K13*L13) -> 15400000 | O13: NAMA | P13: Besi 5 Meter | Q13: Besi 10 Meter | R13: Pipa 5 Meter | S13: Pipa 10 Meter
B14: 9 | D14: 2-Nov | E14: CJ-03 | F14: =VLOOKUP(E14,$O$7:$P$9,2,0) -> Toko Chris John | G14: B-05 | H14: =HLOOKUP(G14,$P$12:$S$13,2,0) -> Besi 5 Meter | I14: 720 | J14: =HLOOKUP(G14,$P$12:$S$14,3,0) -> 250000 | K14: =I14*J14 -> 180000000 | L14: =IF(K14>=100000000,10%,IF(K14>=50000000,5%,0)) -> 0.1 | M14: =K14-(K14*L14) -> 162000000 | O14: HARGA SATUAN | P14: 250000 | Q14: 425000 | R14: 78000 | S14: 140000
B15: 10 | D15: 2-Nov | E15: BK-02 | F15: =VLOOKUP(E15,$O$7:$P$9,2,0) -> Toko Beni Kusuma | G15: B-10 | H15: =HLOOKUP(G15,$P$12:$S$13,2,0) -> Besi 10 Meter | I15: 120 | J15: =HLOOKUP(G15,$P$12:$S$14,3,0) -> 425000 | K15: =I15*J15 -> 51000000 | L15: =IF(K15>=100000000,10%,IF(K15>=50000000,5%,0)) -> 0.05 | M15: =K15-(K15*L15) -> 48450000
B16: 11 | D16: 2-Nov | E16: AB-01 | F16: =VLOOKUP(E16,$O$7:$P$9,2,0) -> Toko Ahmad Budiman | G16: P-05 | H16: =HLOOKUP(G16,$P$12:$S$13,2,0) -> Pipa 5 Meter | I16: 120 | J16: =HLOOKUP(G16,$P$12:$S$14,3,0) -> 78000 | K16: =I16*J16 -> 9360000 | L16: =IF(K16>=100000000,10%,IF(K16>=50000000,5%,0)) -> 0 | M16: =K16-(K16*L16) -> 9360000
B17: 12 | D17: 2-Nov | E17: AB-01 | F17: =VLOOKUP(E17,$O$7:$P$9,2,0) -> Toko Ahmad Budiman | G17: P-10 | H17: =HLOOKUP(G17,$P$12:$S$13,2,0) -> Pipa 10 Meter | I17: 550 | J17: =HLOOKUP(G17,$P$12:$S$14,3,0) -> 140000 | K17: =I17*J17 -> 77000000 | L17: =IF(K17>=100000000,10%,IF(K17>=50000000,5%,0)) -> 0.05 | M17: =K17-(K17*L17) -> 73150000
B18: 13 | D18: 2-Nov | E18: BK-02 | F18: =VLOOKUP(E18,$O$7:$P$9,2,0) -> Toko Beni Kusuma | G18: P-05 | H18: =HLOOKUP(G18,$P$12:$S$13,2,0) -> Pipa 5 Meter | I18: 580 | J18: =HLOOKUP(G18,$P$12:$S$14,3,0) -> 78000 | K18: =I18*J18 -> 45240000 | L18: =IF(K18>=100000000,10%,IF(K18>=50000000,5%,0)) -> 0 | M18: =K18-(K18*L18) -> 45240000
B19: 14 | D19: 3-Nov | E19: AB-01 | F19: =VLOOKUP(E19,$O$7:$P$9,2,0) -> Toko Ahmad Budiman | G19: P-10 | H19: =HLOOKUP(G19,$P$12:$S$13,2,0) -> Pipa 10 Meter | I19: 620 | J19: =HLOOKUP(G19,$P$12:$S$14,3,0) -> 140000 | K19: =I19*J19 -> 86800000 | L19: =IF(K19>=100000000,10%,IF(K19>=50000000,5%,0)) -> 0.05 | M19: =K19-(K19*L19) -> 82460000
B20: 15 | D20: 3-Nov | E20: CJ-03 | F20: =VLOOKUP(E20,$O$7:$P$9,2,0) -> Toko Chris John | G20: P-10 | H20: =HLOOKUP(G20,$P$12:$S$13,2,0) -> Pipa 10 Meter | I20: 900 | J20: =HLOOKUP(G20,$P$12:$S$14,3,0) -> 140000 | K20: =I20*J20 -> 126000000 | L20: =IF(K20>=100000000,10%,IF(K20>=50000000,5%,0)) -> 0.1 | M20: =K20-(K20*L20) -> 113400000
B21: Total QTY | I21: =SUM(I6:I20) -> 7090 | J21: Total Penjualan Bersih | M21: =SUM(M6:M20) -> 1373640000 | N21: 7
B22: Rata-rata QTY | I22: =AVERAGE(I6:I20) -> 472.66667 | J22: Rata-rata Penjualan Bersih | M22: =AVERAGE(M6:M20) -> 91576000 | N22: 8

Sheet Sheet10
B2: No | C2: Kode Surat | D2: Nama Peserta Raw | E2: Status Jenis Surat | F2: Tahun Surat | G2: Bulan Surat | H2: Tanggal Surat | I2: Tanggal | J2: Kode Surat Final | K2: Nama Peserta | L2: Panjang Karakter | M2: Inisial Nama | N2: Inisial & Tanggal
B3: Contoh | C3: S-099/2024/11/25 | D3: rIzKA NuGRaHa | E3: Segera | F3: 2024 | G3: 11 | H3: 25 | I3: 45621 | J3: S-099FL/2024/11/25 | K3: Rizka Nugraha | L3: 13 | M3: RN | N3: RN-25NOV2024
B5: 1 | C5: B-001/2023/08/19 | D5: aNdi sApUtRa | E5: =IF(LEFT(TRIM(C5),1)="S","Segera",IF(LEFT(TRIM(C5),1)="R","Rahasia","Biasa")) -> Biasa | F5: =MID(TRIM(C5),7,4) -> 2023 | G5: =MID(TRIM(C5),12,2) -> 08 | H5: =RIGHT(TRIM(C5),2) -> 19 | I5: =DATE(F5,G5,H5) -> 45157 | J5: =LEFT(TRIM(C5),5)&"FL"&MID(TRIM(C5),6,LEN(TRIM(C5))-5) -> B-001FL/2023/08/19 | K5: =PROPER(TRIM(D5)) -> Andi Saputra | L5: =LEN(K5) -> 12 | M5: =LEFT(K5,1)&MID(K5,FIND(" ",K5)+1,1) -> AS | N5: =M5&"-"&UPPER(TEXT(I5,"DDMMMYYYY")) -> AS-19AUG2023
B6: 2 | C6: R-002/2023/04/20 | D6: bUDi sANtoSo | E6: =IF(LEFT(TRIM(C6),1)="S","Segera",IF(LEFT(TRIM(C6),1)="R","Rahasia","Biasa")) -> Rahasia | F6: =MID(TRIM(C6),7,4) -> 2023 | G6: =MID(TRIM(C6),12,2) -> 04 | H6: =RIGHT(TRIM(C6),2) -> 20 | I6: =DATE(F6,G6,H6) -> 45036 | J6: =LEFT(TRIM(C6),5)&"FL"&MID(TRIM(C6),6,LEN(TRIM(C6))-5) -> R-002FL/2023/04/20 | K6: =PROPER(TRIM(D6)) -> Budi Santoso | L6: =LEN(K6) -> 12 | M6: =LEFT(K6,1)&MID(K6,FIND(" ",K6)+1,1) -> BS | N6: =M6&"-"&UPPER(TEXT(I6,"DDMMMYYYY")) -> BS-20APR2023
B7: 3 | C7: B-003/2024/08/21 | D7: CiTra dEwi | E7: =IF(LEFT(TRIM(C7),1)="S","Segera",IF(LEFT(TRIM(C7),1)="R","Rahasia","Biasa")) -> Biasa | F7: =MID(TRIM(C7),7,4) -> 2024 | G7: =MID(TRIM(C7),12,2) -> 08 | H7: =RIGHT(TRIM(C7),2) -> 21 | I7: =DATE(F7,G7,H7) -> 45525 | J7: =LEFT(TRIM(C7),5)&"FL"&MID(TRIM(C7),6,LEN(TRIM(C7))-5) -> B-003FL/2024/08/21 | K7: =PROPER(TRIM(D7)) -> Citra Dewi | L7: =LEN(K7) -> 10 | M7: =LEFT(K7,1)&MID(K7,FIND(" ",K7)+1,1) -> CD | N7: =M7&"-"&UPPER(TEXT(I7,"DDMMMYYYY")) -> CD-21AUG2024
B8: 4 | C8: B-004/2024/08/22 | D8: dIaN prAseTyo | E8: =IF(LEFT(TRIM(C8),1)="S","Segera",IF(LEFT(TRIM(C8),1)="R","Rahasia","Biasa")) -> Biasa | F8: =MID(TRIM(C8),7,4) -> 2024 | G8: =MID(TRIM(C8),12,2) -> 08 | H8: =RIGHT(TRIM(C8),2) -> 22 | I8: =DATE(F8,G8,H8) -> 45526 | J8: =LEFT(TRIM(C8),5)&"FL"&MID(TRIM(C8),6,LEN(TRIM(C8))-5) -> B-004FL/2024/08/22 | K8: =PROPER(TRIM(D8)) -> Dian Prasetyo | L8: =LEN(K8) -> 13 | M8: =LEFT(K8,1)&MID(K8,FIND(" ",K8)+1,1) -> DP | N8: =M8&"-"&UPPER(TEXT(I8,"DDMMMYYYY")) -> DP-22AUG2024
B9: 5 | C9: S-005/2024/07/23 | D9: ekO waHyUdi | E9: =IF(LEFT(TRIM(C9),1)="S","Segera",IF(LEFT(TRIM(C9),1)="R","Rahasia","Biasa")) -> Segera | F9: =MID(TRIM(C9),7,4) -> 2024 | G9: =MID(TRIM(C9),12,2) -> 07 | H9: =RIGHT(TRIM(C9),2) -> 23 | I9: =DATE(F9,G9,H9) -> 45496 | J9: =LEFT(TRIM(C9),5)&"FL"&MID(TRIM(C9),6,LEN(TRIM(C9))-5) -> S-005FL/2024/07/23 | K9: =PROPER(TRIM(D9)) -> Eko Wahyudi | L9: =LEN(K9) -> 11 | M9: =LEFT(K9,1)&MID(K9,FIND(" ",K9)+1,1) -> EW | N9: =M9&"-"&UPPER(TEXT(I9,"DDMMMYYYY")) -> EW-23JUL2024
B10: 6 | C10: B-006/2024/08/24 | D10: fiTRi aNJaNi | E10: =IF(LEFT(TRIM(C10),1)="S","Segera",IF(LEFT(TRIM(C10),1)="R","Rahasia","Biasa")) -> Biasa | F10: =MID(TRIM(C10),7,4) -> 2024 | G10: =MID(TRIM(C10),12,2) -> 08 | H10: =RIGHT(TRIM(C10),2) -> 24 | I10: =DATE(F10,G10,H10) -> 45528 | J10: =LEFT(TRIM(C10),5)&"FL"&MID(TRIM(C10),6,LEN(TRIM(C10))-5) -> B-006FL/2024/08/24 | K10: =PROPER(TRIM(D10)) -> Fitri Anjani | L10: =LEN(K10) -> 12 | M10: =LEFT(K10,1)&MID(K10,FIND(" ",K10)+1,1) -> FA | N10: =M10&"-"&UPPER(TEXT(I10,"DDMMMYYYY")) -> FA-24AUG2024
B11: 7 | C11: B-007/2024/08/25 | D11: gAlIh pErMAnA | E11: =IF(LEFT(TRIM(C11),1)="S","Segera",IF(LEFT(TRIM(C11),1)="R","Rahasia","Biasa")) -> Biasa | F11: =MID(TRIM(C11),7,4) -> 2024 | G11: =MID(TRIM(C11),12,2) -> 08 | H11: =RIGHT(TRIM(C11),2) -> 25 | I11: =DATE(F11,G11,H11) -> 45529 | J11: =LEFT(TRIM(C11),5)&"FL"&MID(TRIM(C11),6,LEN(TRIM(C11))-5) -> B-007FL/2024/08/25 | K11: =PROPER(TRIM(D11)) -> Galih Permana | L11: =LEN(K11) -> 13 | M11: =LEFT(K11,1)&MID(K11,FIND(" ",K11)+1,1) -> GP | N11: =M11&"-"&UPPER(TEXT(I11,"DDMMMYYYY")) -> GP-25AUG2024
B12: 8 | C12: R-008/2024/08/02 | D12: heNdRA gUnAwAn | E12: =IF(LEFT(TRIM(C12),1)="S","Segera",IF(LEFT(TRIM(C12),1)="R","Rahasia","Biasa")) -> Rahasia | F12: =MID(TRIM(C12),7,4) -> 2024 | G12: =MID(TRIM(C12),12,2) -> 08 | H12: =RIGHT(TRIM(C12),2) -> 02 | I12: =DATE(F12,G12,H12) -> 45506 | J12: =LEFT(TRIM(C12),5)&"FL"&MID(TRIM(C12),6,LEN(TRIM(C12))-5) -> R-008FL/2024/08/02 | K12: =PROPER(TRIM(D12)) -> Hendra Gunawan | L12: =LEN(K12) -> 14 | M12: =LEFT(K12,1)&MID(K12,FIND(" ",K12)+1,1) -> HG | N12: =M12&"-"&UPPER(TEXT(I12,"DDMMMYYYY")) -> HG-02AUG2024
B13: 9 | C13: S-009/2024/08/27 | D13: iNdAh sARi | E13: =IF(LEFT(TRIM(C13),1)="S","Segera",IF(LEFT(TRIM(C13),1)="R","Rahasia","Biasa")) -> Segera | F13: =MID(TRIM(C13),7,4) -> 2024 | G13: =MID(TRIM(C13),12,2) -> 08 | H13: =RIGHT(TRIM(C13),2) -> 27 | I13: =DATE(F13,G13,H13) -> 45531 | J13: =LEFT(TRIM(C13),5)&"FL"&MID(TRIM(C13),6,LEN(TRIM(C13))-5) -> S-009FL/2024/08/27 | K13: =PROPER(TRIM(D13)) -> Indah Sari | L13: =LEN(K13) -> 10 | M13: =LEFT(K13,1)&MID(K13,FIND(" ",K13)+1,1) -> IS | N13: =M13&"-"&UPPER(TEXT(I13,"DDMMMYYYY")) -> IS-27AUG2024
B14: 10 | C14: B-010/2025/06/28 | D14: joKo sUSiLo | E14: =IF(LEFT(TRIM(C14),1)="S","Segera",IF(LEFT(TRIM(C14),1)="R","Rahasia","Biasa")) -> Biasa | F14: =MID(TRIM(C14),7,4) -> 2025 | G14: =MID(TRIM(C14),12,2) -> 06 | H14: =RIGHT(TRIM(C14),2) -> 28 | I14: =DATE(F14,G14,H14) -> 45836 | J14: =LEFT(TRIM(C14),5)&"FL"&MID(TRIM(C14),6,LEN(TRIM(C14))-5) -> B-010FL/2025/06/28 | K14: =PROPER(TRIM(D14)) -> Joko Susilo | L14: =LEN(K14) -> 11 | M14: =LEFT(K14,1)&MID(K14,FIND(" ",K14)+1,1) -> JS | N14: =M14&"-"&UPPER(TEXT(I14,"DDMMMYYYY")) -> JS-28JUN2025
B15: 11 | C15: B-011/2025/08/29 | D15: KaRTiKa pUtRi | E15: =IF(LEFT(TRIM(C15),1)="S","Segera",IF(LEFT(TRIM(C15),1)="R","Rahasia","Biasa")) -> Biasa | F15: =MID(TRIM(C15),7,4) -> 2025 | G15: =MID(TRIM(C15),12,2) -> 08 | H15: =RIGHT(TRIM(C15),2) -> 29 | I15: =DATE(F15,G15,H15) -> 45898 | J15: =LEFT(TRIM(C15),5)&"FL"&MID(TRIM(C15),6,LEN(TRIM(C15))-5) -> B-011FL/2025/08/29 | K15: =PROPER(TRIM(D15)) -> Kartika Putri | L15: =LEN(K15) -> 13 | M15: =LEFT(K15,1)&MID(K15,FIND(" ",K15)+1,1) -> KP | N15: =M15&"-"&UPPER(TEXT(I15,"DDMMMYYYY")) -> KP-29AUG2025
B16: 12 | C16: R-012/2025/08/29 | D16: lEstAri AyU | E16: =IF(LEFT(TRIM(C16),1)="S","Segera",IF(LEFT(TRIM(C16),1)="R","Rahasia","Biasa")) -> Rahasia | F16: =MID(TRIM(C16),7,4) -> 2025 | G16: =MID(TRIM(C16),12,2) -> 08 | H16: =RIGHT(TRIM(C16),2) -> 29 | I16: =DATE(F16,G16,H16) -> 45898 | J16: =LEFT(TRIM(C16),5)&"FL"&MID(TRIM(C16),6,LEN(TRIM(C16))-5) -> R-012FL/2025/08/29 | K16: =PROPER(TRIM(D16)) -> Lestari Ayu | L16: =LEN(K16) -> 11 | M16: =LEFT(K16,1)&MID(K16,FIND(" ",K16)+1,1) -> LA | N16: =M16&"-"&UPPER(TEXT(I16,"DDMMMYYYY")) -> LA-29AUG2025
... B18: 14 | C18: S-014/2025/11/30 | D18: naDiA kUsUmA | E18: =IF(LEFT(TRIM(C18),1)="S","Segera",IF(LEFT(TRIM(C18),1)="R","Rahasia","Biasa")) -> Segera | F18: =MID(TRIM(C18),7,4) -> 2025 | G18: =MID(TRIM(C18),12,2) -> 11 | H18: =RIGHT(TRIM(C18),2) -> 30 | I18: =DATE(F18,G18,H18) -> 45991 | J18: =LEFT(TRIM(C18),5)&"FL"&MID(TRIM(C18),6,LEN(TRIM(C18))-5) -> S-014FL/2025/11/30 | K18: =PROPER(TRIM(D18)) -> Nadia Kusuma | L18: =LEN(K18) -> 12 | M18: =LEFT(K18,1)&MID(K18,FIND(" ",K18)+1,1) -> NK | N18: =M18&"-"&UPPER(TEXT(I18,"DDMMMYYYY")) -> NK-30NOV2025
B21: B | C21: Biasa
B22: R | C22: Rahasia
B23: S | C23: Segera

Sheet Sheet11
B2: No | C2: NPM | D2: Nama Mahasiswa | E2: Angkatan | F2: Jurusan | G2: Kampus Cabang | H2: IPK | I2: Potongan | J2: Biaya Wisuda | K2: Biaya Seluruhnya
B3: 1 | C3: EK20151 | D3: Daniel Hadinata | E3: =MID(C3,3,4) -> 2015 | F3: =VLOOKUP(LEFT(C3,2),$M$4:$N$9,2,0) -> Ekonomi | G3: =IF(MID(C3,7,1)="1","Bekasi",IF(MID(C3,7,1)="2","Depok",IF(MID(C3,7,1)="3","Bogor","-"))) -> Bekasi | H3: 4 | I3: =IF(H3<2.5,0%,IF(H3<=3.5,5%,15%)) -> 0.15 | J3: =IF(VALUE(E3)=2013,5000000,IF(VALUE(E3)=2014,6000000,7000000)) -> 7000000 | K3: =J3-(J3*I3) -> 5950000 | M3: Tabel Jurusan
B4: 2 | C4: TS20142 | D4: Anzy Novitaria | E4: =MID(C4,3,4) -> 2014 | F4: =VLOOKUP(LEFT(C4,2),$M$4:$N$9,2,0) -> Teknik Sipil | G4: =IF(MID(C4,7,1)="1","Bekasi",IF(MID(C4,7,1)="2","Depok",IF(MID(C4,7,1)="3","Bogor","-"))) -> Depok | H4: 3 | I4: =IF(H4<2.5,0%,IF(H4<=3.5,5%,15%)) -> 0.05 | J4: =IF(VALUE(E4)=2013,5000000,IF(VALUE(E4)=2014,6000000,7000000)) -> 6000000 | K4: =J4-(J4*I4) -> 5700000 | M4: Kode | N4: Jurusan
B5: 3 | C5: HK20132 | D5: Siska Sintya | E5: =MID(C5,3,4) -> 2013 | F5: =VLOOKUP(LEFT(C5,2),$M$4:$N$9,2,0) -> Hukum | G5: =IF(MID(C5,7,1)="1","Bekasi",IF(MID(C5,7,1)="2","Depok",IF(MID(C5,7,1)="3","Bogor","-"))) -> Depok | H5: 3.4 | I5: =IF(H5<2.5,0%,IF(H5<=3.5,5%,15%)) -> 0.05 | J5: =IF(VALUE(E5)=2013,5000000,IF(VALUE(E5)=2014,6000000,7000000)) -> 5000000 | K5: =J5-(J5*I5) -> 4750000 | M5: EK | N5: Ekonomi
B6: 4 | C6: EK20153 | D6: Syafira Utami | E6: =MID(C6,3,4) -> 2015 | F6: =VLOOKUP(LEFT(C6,2),$M$4:$N$9,2,0) -> Ekonomi | G6: =IF(MID(C6,7,1)="1","Bekasi",IF(MID(C6,7,1)="2","Depok",IF(MID(C6,7,1)="3","Bogor","-"))) -> Bogor | H6: 2.2 | I6: =IF(H6<2.5,0%,IF(H6<=3.5,5%,15%)) -> 0 | J6: =IF(VALUE(E6)=2013,5000000,IF(VALUE(E6)=2014,6000000,7000000)) -> 7000000 | K6: =J6-(J6*I6) -> 7000000 | M6: HK | N6: Hukum
B7: 5 | C7: TA20151 | D7: Fitri Lestari | E7: =MID(C7,3,4) -> 2015 | F7: =VLOOKUP(LEFT(C7,2),$M$4:$N$9,2,0) -> Arsitek | G7: =IF(MID(C7,7,1)="1","Bekasi",IF(MID(C7,7,1)="2","Depok",IF(MID(C7,7,1)="3","Bogor","-"))) -> Bekasi | H7: 4 | I7: =IF(H7<2.5,0%,IF(H7<=3.5,5%,15%)) -> 0.15 | J7: =IF(VALUE(E7)=2013,5000000,IF(VALUE(E7)=2014,6000000,7000000)) -> 7000000 | K7: =J7-(J7*I7) -> 5950000 | M7: TA | N7: Arsitek
B8: 6 | C8: SP20143 | D8: Alka Cantika | E8: =MID(C8,3,4) -> 2014 | F8: =VLOOKUP(LEFT(C8,2),$M$4:$N$9,2,0) -> Sosial Politik | G8: =IF(MID(C8,7,1)="1","Bekasi",IF(MID(C8,7,1)="2","Depok",IF(MID(C8,7,1)="3","Bogor","-"))) -> Bogor | H8: 3 | I8: =IF(H8<2.5,0%,IF(H8<=3.5,5%,15%)) -> 0.05 | J8: =IF(VALUE(E8)=2013,5000000,IF(VALUE(E8)=2014,6000000,7000000)) -> 6000000 | K8: =J8-(J8*I8) -> 5700000 | M8: TS | N8: Teknik Sipil
B9: 7 | C9: TS20153 | D9: Kevin Wijaya | E9: =MID(C9,3,4) -> 2015 | F9: =VLOOKUP(LEFT(C9,2),$M$4:$N$9,2,0) -> Teknik Sipil | G9: =IF(MID(C9,7,1)="1","Bekasi",IF(MID(C9,7,1)="2","Depok",IF(MID(C9,7,1)="3","Bogor","-"))) -> Bogor | H9: 3.5 | I9: =IF(H9<2.5,0%,IF(H9<=3.5,5%,15%)) -> 0.05 | J9: =IF(VALUE(E9)=2013,5000000,IF(VALUE(E9)=2014,6000000,7000000)) -> 7000000 | K9: =J9-(J9*I9) -> 6650000 | M9: SP | N9: Sosial Politik
B10: 8 | C10: EK20133 | D10: Dimas Mirana | E10: =MID(C10,3,4) -> 2013 | F10: =VLOOKUP(LEFT(C10,2),$M$4:$N$9,2,0) -> Ekonomi | G10: =IF(MID(C10,7,1)="1","Bekasi",IF(MID(C10,7,1)="2","Depok",IF(MID(C10,7,1)="3","Bogor","-"))) -> Bogor | H10: 2.3 | I10: =IF(H10<2.5,0%,IF(H10<=3.5,5%,15%)) -> 0 | J10: =IF(VALUE(E10)=2013,5000000,IF(VALUE(E10)=2014,6000000,7000000)) -> 5000000 | K10: =J10-(J10*I10) -> 5000000
B11: 9 | C11: HK20152 | D11: Linda Fatimah | E11: =MID(C11,3,4) -> 2015 | F11: =VLOOKUP(LEFT(C11,2),$M$4:$N$9,2,0) -> Hukum | G11: =IF(MID(C11,7,1)="1","Bekasi",IF(MID(C11,7,1)="2","Depok",IF(MID(C11,7,1)="3","Bogor","-"))) -> Depok | H11: 3.3 | I11: =IF(H11<2.5,0%,IF(H11<=3.5,5%,15%)) -> 0.05 | J11: =IF(VALUE(E11)=2013,5000000,IF(VALUE(E11)=2014,6000000,7000000)) -> 7000000 | K11: =J11-(J11*I11) -> 6650000 | N11: Kampus Cabang | Q11: Potongan | T11: Biaya Wisuda
B12: 10 | C12: TA20141 | D12: Luis Hamilton | E12: =MID(C12,3,4) -> 2014 | F12: =VLOOKUP(LEFT(C12,2),$M$4:$N$9,2,0) -> Arsitek | G12: =IF(MID(C12,7,1)="1","Bekasi",IF(MID(C12,7,1)="2","Depok",IF(MID(C12,7,1)="3","Bogor","-"))) -> Bekasi | H12: 3 | I12: =IF(H12<2.5,0%,IF(H12<=3.5,5%,15%)) -> 0.05 | J12: =IF(VALUE(E12)=2013,5000000,IF(VALUE(E12)=2014,6000000,7000000)) -> 6000000 | K12: =J12-(J12*I12) -> 5700000 | N12: * Jika karakter ke - 7 NPM = 1, Maka Cabang Bekasi | Q12: * Jika IPK <2,5; Tidak ada potongan ( 0%) | T12: * Jika Angkatan 2013, Biaya Wisuda = 5.000.000
